Workbook

Sheet Project Input
A1: Easy Housing - Calculation Template - January 2026 | B1: Last update: 16-04-2026 by Wolf
A3: Instructions
A4: Open floor plan (.pdf) for which quote has to be made
A5: Fill out the input fields below
A6: Check if parameters like floor area correspond with plan
A7: Open Google Slide: "Easy Housing - Quotation Template Uganda - July 2025"
A8: Update the two tables in the slide
A9: Check if quotation values are properly linked to the template
A10: Do not adjust text or fields in slide template
A11: Create a copy of Google slide doc quote template (from the right country)
A12: Copy the input column in this spreadsheet to the Input Database from column K onwards (for future reference)
A13: Download Google Slide as .pdf and save in the shared quotation folder on the drive
A14: File name format: "YYMMDD - Easy Housing Quotation - Client Name in Location"
... A17: Sign the contract! :)
A20: Project input | B20: Input values | C20: Unit | D20: Comment
A21: Client input
A22: ='Price Calc'!A13 -> Client Name | B22: Funky Jackfruit | C22: name | D22: Full name
A23: ='Price Calc'!A14 -> Contact Details | B23: +256 712 345 678 | C23: phone/mail | D23: Add phone or email
A24: ='Price Calc'!A23 -> Project Location | B24: Sagala | C24: location | D24: Add name municipality (village/town/city)
A25: ='Price Calc'!A24 -> Distance from factory | B25: 50 | C25: km | D25: With Google maps
A26: Date of input | B26: 46023 | C26: date | D26: DD/MM/YYYY
A27: ='Price Calc'!A15 -> Created by | B27: Wolf Bierens | C27: name | D27: Add your full name
A29: Building input (structure parameters)
A30: ='Price Calc'!A18 -> Easy Housing Typology | B30: Mono Pitch (4884) | D30: Select right typology (mm depth of building between brackets to check if not sure)
A31: Number of units (of exactly this type) | B31: 1 | C31: home(s) | D31: Make separate quotes for different models / plans
A32: ='Price Calc'!A59 -> Columns A (1221) | B32: 2 | C32: columns
A33: ='Price Calc'!A60 -> Columns B (2442) | B33: 4 | C33: columns
A34: ='Price Calc'!A61 -> Columns C (3053) | B34: 0 | C34: columns | D34: Not used for A-Frames and Compact Gable | H34: Total GFA | I34: ='Price Calc'!H19 -> 61.2 | J34: sqm (without extra terraces)
A35: ='Price Calc'!A64 -> Interior doors | B35: 6 | C35: pcs
A36: ='Price Calc'!A65 -> Partitions (length) | B36: 27 | C36: linear metres
A37: ='Price Calc'!A66 -> Exterior doors & windows (area) | B37: =D81 -> 10.5 | C37: sqm | D37: Total alu - fill tool below - cell linked to D81
A38: Bedrooms | B38: 2 | C38: number
A39: Bathrooms | B39: 2 | C39: number | D39: Count for plumbing
A40: Kitchen areas | B40: 1 | C40: number | D40: Count for plumbing. Kitchen islands count separately.
A42: Additional options
A43: ='Price Calc'!A41 -> Terrace | B43: 0 | C43: sqm | D43: Inside verandas under roof section are not counted (as they are within typology GFA)
A44: ='Price Calc'!A42 -> Pergola | B44: 0 | C44: sqm | D44: Price for open pergola without sheets
A45: ='Price Calc'!A43 -> Railing open | B45: 0 | C45: linear metres
A46: ='Price Calc'!A44 -> Railing semi-closed | B46: 0 | C46: linear metres
A47: ='Price Calc'!A67 -> Extra staircase (beyond the first) | B47: 0 | C47: pcs | D47: First staircase included - not counted
...

Sheet Project Costs
A5: Easy Housing - Calculation Template 2026
A6: ! Do not share sheets or extracts externally unless authorised !
A8: Project parameters | I8: Calculations | J8: Typologies | L8: Floor frame A | M8: Floor frame B | N8: Floor frame C | O8: Floor frame D (3363) | P8: Foundation | Q8: Wall B low | R8: Wall C low | S8: Wall B high | T8: Wall C high | U8: Roof frame 1221 x 5685 (mono pitch) | V8: Roof frame 1598x 5685 (mono pitch edge) | W8: Roof frame 1221 x 3574 (compact gable) | X8: Roof frame 1689 x 3574 (compact gable edge) | Y8: Roof frame 1221 x 4194 (standard gable) | Z8: Roof frame 1689 x 4194 (standard gable edge) | AA8: Roof frame 1221 x 5435 (large gable) | AB8: Roof frame 1689 x 5435 (large gable edge) | AC8: Roof frame 1221 x 5780 (clerestory upper) | AD8: Roof frame 1689 x 5780 (clerestory upper edge) | AE8: Roof frame 1221 x 4194 (clerestory lower) | AF8: Roof frame 1689 x 4194 (clerestory lower edge)
J9: Mono Pitch (4884) | L9: =2*$E$24 -> 4 | M9: =2*$E$25 -> 8 | N9: =2*$E$26 -> 0 | O9: =2*$E$26 -> 0 | P9: =3*(sum($E$24:$E$26)+1) -> 21 | Q9: =E25+0.5*E24 -> 5 | R9: =E26 -> 0 | S9: =4+E25+0.5*E24 -> 9 | T9: =E26 -> 0 | U9: =E24+2*E25+2.5*E26-2 -> 8 | V9: 2
A10: Project location parameters | B10: Kampala, Uganda | J10: Compact Gable (6106) | L10: 0 | M10: 0 | N10: =E25*2+E24 -> 10 | O10: =2*$E$26 -> 0 | P10: =3*(sum($E$24:$E$26)+1) -> 21 | Q10: =E25*2+E24 -> 10 | R10: 0 | S10: 0 | T10: 4 | W10: =(E24+2*E25+2.5*E26-2)*2 -> 16 | X10: 4
A11: Project code | B11: EH-000 | J11: Standard Gable (7326) | L11: =3*$E$24 -> 6 | M11: =3*$E$25 -> 12 | N11: =3*$E$26 -> 0 | O11: =2*$E$26 -> 0 | P11: =4*(sum($E$24:$E$26)+1) -> 28 | Q11: =E25*2+E24 -> 10 | R11: =E26*2 -> 0 | S11: 6 | T11: 0 | Y11: =(E24+2*E25+2.5*E26-2)*2 -> 16 | Z11: 4
A12: Project name | J12: Large Gable (9768) | L12: =4*$E$24 -> 8 | M12: =4*$E$25 -> 16 | N12: =4*$E$26 -> 0 | O12: =2*$E$26 -> 0 | P12: =5*(sum($E$24:$E$26)+1) -> 35 | Q12: =E25*2+E24 -> 10 | R12: =E26*2 -> 0 | S12: 8 | T12: 0 | AA12: =Y11 -> 16 | AB12: =Z11 -> 4
A13: Project Location | B13: Greater Kampala (<100km from factory) | J13: Standard Clerestory (7326) | L13: =3*$E$24 -> 6 | M13: =3*$E$25 -> 12 | N13: =3*$E$26 -> 0 | O13: =2*$E$26 -> 0 | P13: =4*(sum($E$24:$E$26)+1) -> 28 | Q13: =E25+0.5*E24 -> 5 | R13: =E26 -> 0 | S13: =6+E25+0.5*E24 -> 11 | T13: =E26 -> 0 | AC13: =U9 -> 8 | AD13: 2 | AE13: =AC13 -> 8 | AF13: 2
A14: Client name | B14: Example calculation | J14: Large Clerestory (8547) | L14: =3.5*$E$24 -> 7 | M14: =3.5*$E$25 -> 14 | N14: =3.5*$E$26 -> 0 | O14: =2*$E$26 -> 0 | P14: =5*(sum($E$24:$E$26)+1) -> 35 | Q14: =Q13 -> 5 | R14: =R13 -> 0 | S14: =S13+1 -> 12 | T14: =T13 -> 0 | AC14: =AC13 -> 8 | AD14: 2 | AE14: =AC13 -> 8 | AF14: 2
J15: A Frame Compact (3663) | O15: =E25+0.5*E24 -> 5 | P15: =2*(sum($E$24:$E$26)+1) -> 14 | T15: 2 | U15: =2*(E24+2*E25+2.5*E26-2) -> 16 | V15: 4
J16: A Frame Standard (4884) | M16: =2*E25+E24 -> 10 | O16: =2*$E$26 -> 0 | P16: =3*(sum($E$24:$E$26)+1) -> 21 | S16: 4 | U16: =2*(E24+2*E25+2.5*E26-2) -> 16 | V16: 4
J17: A Frame Large (6106) | N17: =2*E25 -> 8 | O17: =2*$E$26 -> 0 | P17: =3*(sum($E$24:$E$26)+1) -> 21 | T17: 4 | U17: =2*(E24+2*E25+2.5*E26-2) -> 16 | V17: 4
A18: Date created | B18: =today() -> 46128 | I18: Selected: | J18: =E22 -> Mono Pitch (4884) | L18: =index(L9:L17,match($J$18,$J$9:$J$17,0),1) -> 4 | M18: =index(M9:M17,match($J$18,$J$9:$J$17,0),1) -> 8 | N18: =index(N9:N17,match($J$18,$J$9:$J$17,0),1) -> 0 | O18: =index(O9:O17,match($J$18,$J$9:$J$17,0),1) -> 0 | P18: =index(P9:P17,match($J$18,$J$9:$J$17,0),1) -> 21 | Q18: =index(Q9:Q17,match($J$18,$J$9:$J$17,0),1) -> 5 | R18: =index(R9:R17,match($J$18,$J$9:$J$17,0),1) -> 0 | S18: =index(S9:S17,match($J$18,$J$9:$J$17,0),1) -> 9 | ... AF18: =index(AF9:AF17,match($J$18,$J$9:$J$17,0),1)
A21: Building parameters | D21: Quick Input Tool - now linked to input tab, do not overwrite | J21: Subcontractor / supplier budget overview * | O21: Labour time overview
A22: Building typology | B22: =E22 -> Mono Pitch (4884) | D22: Typology | E22: ='Project Input'!B30 -> Mono Pitch (4884)
A23: Gross floor surface (sqm) | B23: =sum(V68:V70)+0.044*(A75*2.442+A76*3.053+A77*2.442+A78*3.053) -> 61.137912 | D23: Name | E23: ='Project Input'!B22 -> Funky Jackfruit | J23: Description | M23: =B37&" ex VAT **" -> UGX ex VAT ** | O23: Description | R23: Labour days
A24: Decking surface area (sqm) | B24: =sum(V72:V74) -> 0 | D24: Floor A - 1221 | E24: ='Project Input'!B32 -> 2 | F24: columns | J24: Foundation blocks | M24: =J121 -> 3364420.2 | O24: Prefabrication labour | R24: =roundup(sum(T68:T94)/8,0) -> 50
A25: Net floor surface without decking/walls | B25: =sum(V68:V70)-0.099*(A75*2.442+A76*3.053+A77*2.442+A78*3.053) -> 56.249028 | D25: Floor B - 2442 | E25: ='Project Input'!B33 -> 4 | F25: columns | G25: use for compact gable | J25: Aluminium doors and windows | M25: =sum(J99:J114) -> 0 | O25: Foundation casting and placement | R25: =round(T121/8,0) -> 9
A26: Exterior wall surface (sqm) | B26: =sum(V75:V78) -> 104.1977 | D26: Floor C - 3053 | E26: ='Project Input'!B34 -> 0 | F26: columns | J26: Interior doors | M26: =J122 -> 4440000 | O26: Site placement labour | R26: =roundup(0.5*$B$23,0) -> 31
A27: Outer windows and doors (sqm) | B27: =sum(V99:V114)+A115 -> 10.5 | D27: Partitions | E27: ='Project Input'!B36 -> 27 | F27: m1 / default at 30% of GFA | G27: 0.3 | H27: =G23*B19 | J27: Roof sheets, inc screws, ridges, gutters, labour | M27: =J123 -> 3372996.5 | O27: Site finishings (steps, fascia, skirts, substrate) | R27: =roundup(B23*0.2+2+A125*0.2+A126,0) -> 20
A28: Net facade surface (sqm) | B28: =B26-B27 -> 93.697698 | D28: Interior doors | E28: ='Project Input'!B35 -> 6 | F28: pcs | J28: Paint works interior and exterior | M28: =J124 -> 8096898.2 | O28: Paint works (on site) | R28: =Round(T124/8,0) -> 32
A29: Partition wall surface (sqm) | B29: =V79*2 -> 162 | D29: Aluminium | E29: ='Project Input'!B37 -> 10.5 | F29: sqm / default at 20% of ext wall surface | G29: 0.2 | H29: =G25*B22 | J29: Truck frames transport to sites <100 km | M29: =J137 -> 1131051.4 | O29: Project manager | R29: =round(2+0.1*B23,0) -> 8
A30: Roof surface (sqm) | B30: =sum(V82:V93) -> 74.522832 | D30: Extra ext. wall | E30: 0 | F30: grid steps 61cm (indents etc) | J30: Electricity | M30: =J155 -> 5585343.4 | O30: Total | R30: =SUM(R24:R29) -> 150 | S30: days
A31: Number ext doors and windows (if filled) | B31: =sum(A99:A114) -> 0 | D31: Veranda A | E31: 0 | F31: frames | J31: Plumbing | M31: =J156 -> 2528447.8 | R31: =R30*8 -> 1200 | S31: hours
A32: Foundation type | B32: ='Bill of Quantities'!C35 -> Foundation block | D32: Veranda B | E32: 0 | F32: frames | J32: Cement boards bathrooms | M32: =J126 -> 2640698.3
A33: Foundation average height (mm) | B33: 400 | D33: Veranda C | E33: =roundup('Project Input'!B43/(3.05*2.44),0) -> 0 | F33: frames | J33: Plywood | M33: =sum('Bill of Quantities'!P52:P55)*B38 -> 4537575.9
A34: Distance from workshop (km) | B34: 100 | D34: Bathrooms | E34: ='Project Input'!B39 -> 2 | F34: bathroom(s) | J34: Timber | M34: ='Timber Order'!H35*'Bill of Quantities'!D14*B38 -> 10051388
J35: Roof insulation | M35: ='Bill of Quantities'!P83*B38 -> 396825
A36: Price information | J36: Wall insulation | M36: ='Bill of Quantities'!P84*B38 -> 982364.73
A37: ='Location Data'!C5 -> Currency | B37: {=index('Location Data'!C:C,MATCH($B$10,'Location Data'!A:A,0),1)} -> UGX | J37: Total | M37: =SUM(M23:M36) -> 47128009
A38: ='Location Data'!D5 -> Conversion rate from USD | B38: {=index('Location Data'!D:D,MATCH($B$10,'Location Data'!A:A,0),1)} -> 3700
A39: Margin | B39: 0.1
A40: ='Location Data'!E5 -> Value added tax (VAT) | B40: {=index('Location Data'!E:E,MATCH($B$10,'Location Data'!A:A,0),1)} -> 0.18 | J40: * subcontractor budgets are exclusive of VAT
A41: Cost price in USD ex VAT | B41: =D63 -> 20866.883 | J41: ** budgets incl all material, labour,transportation costs
A42: Margin | B42: =B41*B39 -> 2086.6883 | D42: Standard models
A43: Licence Fee Easy Building | B43: =C134 -> 1528.4478
A44: Sales price in USD ex VAT | B44: =B41+B42 -> 22953.572 | D44: Typology | E44: =J9 -> Mono Pitch (4884) | F44: =E44 -> Mono Pitch (4884) | G44: =F44 -> Mono Pitch (4884) | H44: =G44 -> Mono Pitch (4884) | I44: Compact Gable 6106 | J44: Compact Gable 6106 | K44: Compact Gable 6106 | L44: Compact Gable 6106 | M44: Compact Gable 6106 | N44: Standard Gable 7326 | O44: Standard Gable 7326 | P44: Standard Gable 7326 | Q44: Large Gable 9768 | R44: Clerestory 8547 | S44: Clerestory 8547 | T44: Clerestory 8547 | U44: Compact Gable 6106 | V44: Clerestory 7326 | W44: Clerestory 8547 | X44: Compact Gable 6106 | Y44: Mono Pitch 4884 | Z44: Clerestory 8547 | AA44: Mono Pitch 4884 | AB44: Clerestory 8547 | AC44: A Frame Large | AD44: A Frame Compact | AE44: A Frame Standard
A45: Price in USD in VAT | B45: =B44*B40+B44 -> 27085.214 | D45: Building width | E45: Studio | F45: 1BR Mono | G45: 2BR Mono | H45: 3BR Mono | I45: 1BR Compact Gable | J45: 2BR Compact Gable | K45: 3BR Compact Gable | L45: 4BR Compact Gable | M45: 2BR Comfort Compact Gable | N45: 2BR Gable | O45: 3BR Gable | P45: 4BR Gable | Q45: 3BR Large Gable | R45: 2BR Clerestory | S45: 4BR Clerestory | T45: Nisha's | U45: John's | V45: Sarah's | W45: Naomi & Jesse | X45: Mlango Farm | Y45: Milly | Z45: Naomi & Jesse | AA45: Janet | AB45: Pius O | AC45: Zziwa test | AD45: Compact A Frame | AE45: Standard A Frame
A46: Price per sqm GFA in USD in VAT | B46: =B45/B23 -> 443.01831 | D46: Floor A - 1221 | E46: 0 | F46: 0 | G46: 0 | H46: 0 | I46: 0 | J46: 0 | K46: 1 | L46: 0 | M46: 0 | N46: 0 | O46: 0 | P46: 0 | Q46: 0 | R46: 1 | S46: 1 | T46: 2 | U46: 0 | V46: 0 | W46: 2 | X46: 0 | Y46: 0 | Z46: 2 | AA46: 0 | AB46: 2 | AC46: 0 | AD46: 0 | AE46: 0
D47: Floor B - 2442 | E47: 2 | F47: 0 | G47: 1 | H47: 0 | I47: 3 | J47: 4 | K47: 4 | L47: 5 | M47: 5 | N47: 1 | O47: 4 | P47: 2 | Q47: 2 | R47: 0 | S47: 0 | T47: 0 | U47: 4 | V47: 2 | W47: 2 | X47: 4 | Y47: 1 | Z47: 2 | AA47: 0 | AB47: 4 | AC47: 4 | AD47: 3 | AE47: 3
...

Sheet Project Output
A1: Create printable output tab with following info
A2: Serves as direct quotation output to send to clients or for internal review
A3: Create macro buttons here for saving input to database tab and for creating PDF printing command
A5: Outputs
A6: Client info, name location, distance etc
A7: Building info, sqm gfa, facade, doors, alu etc
A8: Price breakdown (based on price calc tab) add dropdown function for Country
A9: Price columns should be in VAT in right country currency
A10: Print selection should fit on 2 A4 pages as PDF - add instructions for macros
A11: Add quotation and general disclaimers
A12: Add info on timeline, location reqs etc
A13: Integrate distance charge hidden or explicit in price?

Sheet Project Budget
A1: Project budget overview for PMs
A3: Together with BOQ should give a complete project budget and procurement overview
A4: Export as a copy tab to new spreadsheet, as work file for PM to keep track
A6: Suppliers
A7: Timber, ply, screws, sheets, boards, etc
A8: Labour overview
A9: Site estimated budget and tab to keep track of site expenses?
A10: Subcontractors for MEP and options?
A11: Extra options as separate lines, including cost vs price breakdown

Sheet Price Calc
A1: Easy Housing - Price Calculation
A4: General Information | G4: General Information
A5: Quotation Date | B5: =today() -> 46128 | G5: Quotation Date | H5: =today() -> 46128
A6: Validity | B6: One month | G6: Validity | H6: One month
A8: All prices are inclusive of VAT | G8: All prices are inclusive of VAT
A9: All prices are in Ugandan Shillings (UGX) | G9: All prices are in Kenyan Shillings (KES)
A10: No rights can be derived from this quote | G10: No rights can be derived from this quote
A12: Client Information | G12: Client Information
A13: Client Name | B13: ='Project Input'!B22 -> Funky Jackfruit | G13: Client Name | H13: =B13 -> Funky Jackfruit
A14: Contact Details | B14: ='Project Input'!B23 -> +256 712 345 678 | G14: Contact Details | H14: =B14 -> +256 712 345 678
A15: Created by | B15: ='Project Input'!B27 -> Wolf Bierens | G15: Quotation Made By | H15: =B15 -> Wolf Bierens
A17: Project information | G17: Project information
A18: Easy Housing Typology | B18: =B58 -> Mono Pitch (4884) | G18: Easy Housing Typology | H18: =B18 -> Mono Pitch (4884)
A19: Gross Floor Area (sqm) | B19: =B62 -> 61.2 | G19: Gross Floor Area (sqm) | H19: =B19 -> 61.2
A20: Terrace (sqm) | B20: =B41 -> 0 | G20: Terrace (sqm) | H20: =B20 -> 0
A21: Bedrooms | B21: =B69 -> 2 | G21: Bedrooms | H21: =B21 -> 2
A22: Bathrooms | B22: =B70 -> 2 | G22: Bathrooms | H22: =B22 -> 2
A23: Project Location | B23: ='Project Input'!B24 -> Sagala | G23: Project Location | H23: =B23 -> Sagala
A24: Distance from factory | B24: ='Project Input'!B25 -> 50 | G24: Distance from factory | H24: =B24 -> 50
A26: Quotation Price Breakdown | G26: Quotation Price Breakdown
A28: Price Breakdown | E28: Price (UGX) | G28: Price Breakdown | K28: Price (KES)
A30: Complete Easy Home | E30: =E81 -> 110966200 | G30: Complete Easy Home | K30: =G81 -> 4205080
A31: Includes: | G31: Includes:
A32: All labour and overhead | G32: All labour and overhead
A33: Full structure | G33: Full structure
A34: Paintworks | G34: Paintworks
A35: Electrical installations | G35: Electrical installations
A36: Plumbing (if any) | G36: Plumbing (if any)
A37: See price list for more details | G37: See price list for more details
A39: Additional options | B39: Size | C39: Unit | D39: Unit price | E39: Price (UGX) | G39: Additional options | H39: Size | I39: Unit | J39: Unit price | K39: Price (KES)
A40: Burglar bars | B40: ='Project Input'!B48 -> 0 | C40: sqm | D40: 250000 | E40: =B40*D40 -> 0 | F40: For standard design burglar bars of steel | G40: Burglar bars | H40: =B40 -> 0 | I40: =C40 -> sqm | J40: 7500 | K40: =H40*J40 -> 0
A41: Terrace | B41: ='Project Input'!B43 -> 0 | C41: sqm | D41: 300000 | E41: =B41*D41 -> 0 | F41: In standard size frames, including linseed oil finishing and foundation work | G41: Terrace | H41: =B41 -> 0 | I41: =C41 -> sqm | J41: 12000 | K41: =H41*J41 -> 0
A42: Pergola | B42: ='Project Input'!B44 -> 0 | C42: sqm | D42: 100000 | E42: =B42*D42 -> 0 | F42: For an open structure pergola with beams every 60 cm | G42: Pergola | H42: =B42 -> 0 | I42: =C42 -> sqm | J42: 4000 | K42: =H42*J42 -> 0
A43: Railing open | B43: ='Project Input'!B45 -> 0 | C43: m1 | D43: 90000 | E43: =B43*D43 -> 0 | F43: With studs every 1.2m | G43: Railing open | H43: =B43 -> 0 | I43: =C43 -> m1 | J43: 3500 | K43: =H43*J43 -> 0
A44: Railing semi-closed | B44: ='Project Input'!B46 -> 0 | C44: m1 | D44: 180000 | E44: =B44*D44 -> 0 | F44: With studs every 20 cm so that kids and animals cannot fall through | G44: Railing semi-closed | H44: =B44 -> 0 | I44: =C44 -> m1 | J44: 7000 | K44: =H44*J44 -> 0
A45: Wheelchair ramp | B45: ='Project Input'!B49 -> 0 | C45: pcs | D45: 1500000 | E45: =B45*D45 -> 0 | F45: For an average ramp of around 5m long (low inclination) | G45: Wheelchair ramp | H45: =B45 -> 0 | I45: =C45 -> pcs | J45: 6500 | K45: =H45*J45 -> 0
A46: Tiles | C46: total | E46: ='Project Input'!B50 -> 0 | G46: Tiles | I46: =C46 -> total | K46: ='Project Input'!B50 -> 0
A47: Sanitary wares | C47: total | E47: ='Project Input'!B51 -> 0 | G47: Sanitary wares | I47: =C47 -> total | K47: ='Project Input'!B51 -> 0
A48: Biodigester | C48: total | E48: ='Project Input'!B52 -> 0 | G48: Biodigester | I48: =C48 -> total | K48: ='Project Input'!B52 -> 0
A49: ="Other options: "&'Project Input'!B53 -> Other options: | E49: ='Project Input'!B54 | G49: ='Project Input'!A54 -> Other option(s) price | I49: =C49 | K49: ='Project Input'!B54
...

Sheet Bill of Quantities
A1: Bill of Quantities | D1: Specifications | M1: Item costs | P1: Project costs | Q1: Cost database | X1: Orderlist | AB1: =sum(AB88:AB148) -> 10.168282 | AC1: =sum(AC88:AC148) -> 10.722991 | AE1: =sum(AE88:AE148) -> 0.55470827 | AF1: =AE1/AC1 -> 0.051730742
A2: # | B2: Unit | C2: Item | D2: Width (mm) | E2: Height (mm) | F2: Length (mm) | G2: Volume (m3) | H2: Weight (kg) | I2: Carbon storage (kg CO2) | J2: Labour (min) | K2: Structure | L2: Type | M2: Item cost ($) | N2: Labour cost ($) | O2: Total cost ($) | Q2: ='Location Data'!A6 -> Kampala, Uganda | R2: ='Location Data'!A7 -> West Nile, Uganda | S2: ='Location Data'!A8 -> Beira, Mozambique | T2: ='Location Data'!A9 -> Maputo, Mozambique | U2: ='Location Data'!A10 -> Accra, Ghana | V2: ='Location Data'!A11 -> Arusha, Tanzania | W2: ='Location Data'!A12 -> Nairobi, Kenya | X2: Sawn from | Y2: Gross fraction | Z2: Sum | AA2: Loss | AB2: Net vol | AC2: Gross vol | AD2: Gross vol / item | AE2: Project loss | AF2: Loss percentage
A4: Project name | C4: ='Project Costs'!B12
A5: ='Project Costs'!A13 -> Project Location | C5: ='Project Costs'!B13 -> Greater Kampala (<100km from factory)
A6: ='Project Costs'!A14 -> Client name | C6: ='Project Costs'!B14 -> Example calculation
A8: Country parameters | C8: Description | D8: Value
C9: Selected location | D9: ='Project Costs'!B10 -> Kampala, Uganda
C10: ='Location Data'!B5 -> Country | D10: {=index('Location Data'!B:B,match($D$9,'Location Data'!A:A,0),1)} -> Uganda
C11: ='Location Data'!G5 -> Distance from sawmill | D11: {=index('Location Data'!G:G,match($D$9,'Location Data'!A:A,0),1)} -> 100
C12: ='Location Data'!F5 -> Forestry partner | D12: {=index('Location Data'!F:F,match($D$9,'Location Data'!A:A,0),1)} -> Green Resources, Jinja
C13: ='Location Data'!H5 -> Timber species | D13: {=index('Location Data'!H:H,match($D$9,'Location Data'!A:A,0),1)} -> Pinus caribaea
C14: ='Location Data'!I5 -> Price per m3 (normal - ex vat, ex mill) | D14: =I14*G14 -> 252 | F14: Offcut loss | G14: 1 | H14: Bulk price | I14: {=index('Location Data'!I:I,match($D$9,'Location Data'!A:A,0),1)} -> 252
C15: ='Location Data'!J5 -> Price per m3 (profiled) | D15: =I15*G15 -> 260 | F15: Offcut loss | G15: 1 | H15: Bulk price | I15: {=index('Location Data'!J:J,match($D$9,'Location Data'!A:A,0),1)} -> 260
C16: ='Location Data'!K5 -> Timber density (wet) | D16: {=index('Location Data'!K:K,match($D$9,'Location Data'!A:A,0),1)} -> 561
C17: ='Location Data'!L5 -> Moisture content | D17: {=index('Location Data'!L:L,match($D$9,'Location Data'!A:A,0),1)} -> 0.12
C18: ='Location Data'!M5 -> Timber density (dry) | D18: {=index('Location Data'!M:M,match($D$9,'Location Data'!A:A,0),1)} -> 493
C19: ='Location Data'!N5 -> Carpenter cost (day) | D19: {=index('Location Data'!N:N,match($D$9,'Location Data'!A:A,0),1)} -> 15
C20: Carbon storage in CO2 per kg dry timber | D20: 1.833
A22: Screws and fasteners | Q22: Now calculating with mostly local prices
A23: =sumif('Structures Database'!B:B,C23,'Structures Database'!W:W) -> 1460 | B23: pcs | C23: Screw 3.5x40 small head screw SHS3540 | D23: 3.5 | F23: 40 | G23: =(D23/2)^2*PI()*F23/1000000000 -> 3.848451e-07 | H23: =G23*7700 -> 0.0029633073 | J23: 1 | K23: Screw | L23: Flooring | M23: =index(23:23,1,match($D$9,$2:$2,0)) -> 0.046297556 | N23: =J23*$D$19/(8*60) -> 0.03125 | O23: =M23+N23 -> 0.077547556 | P23: =A23*O23 -> 113.21943 | Q23: =0.0253*$X$26 -> 0.046297556 | R23: =$Q23 -> 0.046297556 | S23: =$Q23 -> 0.046297556 | T23: =$Q23 -> 0.046297556 | U23: =$Q23 -> 0.046297556 | V23: =$Q23 -> 0.046297556 | W23: =Q23 -> 0.046297556 | X23: Screw specs from Rotho Blaas now assumed with 25% import tax, 15% withholding tax, and 25% freight costs (USD 500 on USD 2500 order) across markets. VAT is added separately per country.
A24: =sumif('Structures Database'!B:B,C24,'Structures Database'!W:W) -> 0 | B24: pcs | C24: Screw 3.5x50 stainless small head screw SHS3550AS | D24: 3.5 | F24: 50 | G24: =(D24/2)^2*PI()*F24/1000000000 -> 4.8105638e-07 | H24: =G24*7700 -> 0.0037041341 | J24: 1 | K24: Screw | L24: Decking / Facade | M24: =index(24:24,1,match($D$9,$2:$2,0)) -> 0.070086815 | N24: =J24*$D$19/(8*60) -> 0.03125 | O24: =M24+N24 -> 0.10133681 | P24: =A24*O24 -> 0 | Q24: =0.0383*$X$26 -> 0.070086815 | R24: =$Q24 -> 0.070086815 | S24: =$Q24 -> 0.070086815 | T24: =$Q24 -> 0.070086815 | U24: =$Q24 -> 0.070086815 | V24: =$Q24 -> 0.070086815 | W24: =Q24 -> 0.070086815 | X24: Screw specs from Rotho Blaas now assumed with 25% import tax, 15% withholding tax, and 25% freight costs (USD 500 on USD 2500 order) across markets. VAT is added separately per country.
A25: =sumif('Structures Database'!B:B,C25,'Structures Database'!W:W) -> 0 | B25: pcs | C25: Screw 4 x 50 Stainless A2 SCA450 | D25: 4 | F25: 50 | G25: =(D25/2)^2*PI()*F25/1000000000 -> 6.2831853e-07 | H25: =G25*7700 -> 0.0048380527 | J25: 1 | K25: Screw | L25: Outdoor | M25: =index(25:25,1,match($D$9,$2:$2,0)) -> 0.1024768 | N25: =J25*$D$19/(8*60) -> 0.03125 | O25: =M25+N25 -> 0.1337268 | P25: =A25*O25 -> 0 | Q25: =0.056*$X$26 -> 0.1024768 | R25: =$Q25 -> 0.1024768 | S25: =$Q25 -> 0.1024768 | T25: =$Q25 -> 0.1024768 | U25: =$Q25 -> 0.1024768 | V25: =$Q25 -> 0.1024768 | W25: =Q25 -> 0.1024768 | X25: Import factor
A26: =sumif('Structures Database'!B:B,C26,'Structures Database'!W:W) -> 4966.8427 | B26: pcs | C26: Screw 4x40 semi threaded HBS440 | D26: 4 | F26: 40 | G26: =(D26/2)^2*PI()*F26/1000000000 -> 5.0265482e-07 | H26: =G26*7700 -> 0.0038704421 | J26: 1 | K26: Screw | L26: Boards | M26: =index(26:26,1,match($D$9,$2:$2,0)) -> 0.012 | N26: =J26*$D$19/(8*60) -> 0.03125 | O26: =M26+N26 -> 0.04325 | P26: =A26*O26 -> 214.81595 | Q26: 0.012 | R26: =$Q26 -> 0.012 | S26: =$Q26 -> 0.012 | T26: =$Q26 -> 0.012 | U26: =$Q26 -> 0.012 | V26: =$Q26 -> 0.012 | W26: =Q26 -> 0.012 | X26: =(2475+600+(0.35+0.06+0.015)*2475+680000/3700+218.45)/2475 -> 1.8299429
A27: =sumif('Structures Database'!B:B,C27,'Structures Database'!W:W) -> 2307.5998 | B27: pcs | C27: Screw 4x60 semi threaded HBS460 | D27: 4 | F27: 60 | G27: =(D27/2)^2*PI()*F27/1000000000 -> 7.5398224e-07 | H27: =G27*7700 -> 0.0058056632 | J27: 1 | K27: Screw | L27: Back Battens | M27: =index(27:27,1,match($D$9,$2:$2,0)) -> 0.018 | N27: =J27*$D$19/(8*60) -> 0.03125 | O27: =M27+N27 -> 0.04925 | P27: =A27*O27 -> 113.64929 | Q27: 0.018 | R27: =$Q27 -> 0.018 | S27: =$Q27 -> 0.018 | T27: =$Q27 -> 0.018 | U27: =$Q27 -> 0.018 | V27: =$Q27 -> 0.018 | W27: =Q27 -> 0.018
A28: =sumif('Structures Database'!B:B,C28,'Structures Database'!W:W) -> 0 | B28: pcs | C28: Screw 5x80 semi threaded HBS580 | D28: 5 | F28: 80 | G28: =(D28/2)^2*PI()*F28/1000000000 -> 1.5707963e-06 | H28: =G28*7700 -> 0.012095132 | J28: 1 | K28: Screw | L28: Frames | M28: =index(28:28,1,match($D$9,$2:$2,0)) -> 0.146 | N28: =J28*$D$19/(8*60) -> 0.03125 | O28: =M28+N28 -> 0.17725 | P28: =A28*O28 -> 0 | Q28: 0.146 | R28: =$Q28 -> 0.146 | S28: =$Q28 -> 0.146 | T28: =$Q28 -> 0.146 | U28: =$Q28 -> 0.146 | V28: =$Q28 -> 0.146 | W28: =Q28 -> 0.146
A29: =sumif('Structures Database'!B:B,C29,'Structures Database'!W:W) -> 760.22222 | B29: pcs | C29: Screw 6x100 semi threaded HBS6100 | D29: 6 | F29: 100 | G29: =(D29/2)^2*PI()*F29/1000000000 -> 2.8274334e-06 | H29: =G29*7700 -> 0.021771237 | J29: 1 | K29: Screw | L29: Frames | M29: =index(29:29,1,match($D$9,$2:$2,0)) -> 0.06 | N29: =J29*$D$19/(8*60) -> 0.03125 | O29: =M29+N29 -> 0.09125 | P29: =A29*O29 -> 69.370277 | Q29: 0.06 | R29: =$Q29 -> 0.06 | S29: =$Q29 -> 0.06 | T29: =$Q29 -> 0.06 | U29: =$Q29 -> 0.06 | V29: =$Q29 -> 0.06 | W29: =Q29 -> 0.06
A30: =sumif('Structures Database'!B:B,C30,'Structures Database'!W:W) -> 1782.0344 | B30: pcs | C30: Screw 6x120 semi threaded HBS6120 | D30: 6 | F30: 120 | G30: =(D30/2)^2*PI()*F30/1000000000 -> 3.3929201e-06 | H30: =G30*7700 -> 0.026125485 | J30: 1 | K30: Screw | L30: Frames | M30: =index(30:30,1,match($D$9,$2:$2,0)) -> 0.06 | N30: =J30*$D$19/(8*60) -> 0.03125 | O30: =M30+N30 -> 0.09125 | P30: =A30*O30 -> 162.61064 | Q30: 0.06 | R30: =$Q30 -> 0.06 | S30: =$Q30 -> 0.06 | T30: =$Q30 -> 0.06 | U30: =$Q30 -> 0.06 | V30: =$Q30 -> 0.06 | W30: =Q30 -> 0.06
A31: =sumif('Structures Database'!B:B,C31,'Structures Database'!W:W) -> 68 | B31: pcs | C31: Screw 6x160 semi threaded HBS6160 | D31: 6 | F31: 160 | G31: =(D31/2)^2*PI()*F31/1000000000 -> 4.5238934e-06 | H31: =G31*7700 -> 0.034833979 | J31: 1 | K31: Screw | L31: Frames | M31: =index(31:31,1,match($D$9,$2:$2,0)) -> 0.41891054 | N31: =J31*$D$19/(8*60) -> 0.03125 | O31: =M31+N31 -> 0.45016054 | P31: =A31*O31 -> 30.610917 | Q31: =0.22892*$X$26 -> 0.41891054 | R31: =$Q31 -> 0.41891054 | S31: =$Q31 -> 0.41891054 | T31: =$Q31 -> 0.41891054 | U31: =$Q31 -> 0.41891054 | V31: =$Q31 -> 0.41891054 | W31: =Q31 -> 0.41891054
A32: =sumif('Structures Database'!B:B,C32,'Structures Database'!W:W) -> 298.09133 | B32: pcs | C32: Corrugated roof screw 67 mm | D32: 6 | F32: 67 | G32: =(D32/2)^2*PI()*F32/1000000000 -> 1.8943804e-06 | H32: =G32*7700 -> 0.014586729 | J32: 1 | K32: Screw | L32: Roofing | M32: =index(32:32,1,match($D$9,$2:$2,0)) -> 0.11756757 | N32: =J32*$D$19/(8*60) -> 0.03125 | O32: =M32+N32 -> 0.14881757 | P32: =A32*O32 -> 44.361226 | Q32: =435/'Location Data'!$D$6 -> 0.11756757 | R32: =$Q32 -> 0.11756757 | S32: =$Q32 -> 0.11756757 | T32: =$Q32 -> 0.11756757 | U32: =$Q32 -> 0.11756757 | V32: =$Q32 -> 0.11756757 | W32: =Q32 -> 0.11756757
A34: Foundation materials
A35: =sumif('Structures Database'!B:B,C35,'Structures Database'!W:W) -> 21 | B35: pcs | C35: Foundation block | D35: 300 | E35: 400 | F35: 300 | G35: =D35*E35*F35/1000000000 -> 0.036 | H35: =G35*2400 -> 86.4 | I35: 0 | J35: 180 | K35: Foundation | L35: Point | M35: {=index(35:35,1,match($D$9,$2:$2,0))} -> 0 | N35: =J35*$D$19/(8*60) -> 5.625 | O35: =M35+N35 -> 5.625 | P35: =A35*O35 -> 118.125 | Q35: 0 | R35: 0 | S35: 0 | T35: 0 | U35: 0 | V35: 0 | W35: 0
A36: =sumif('Structures Database'!B:B,C36,'Structures Database'!W:W) -> 6.3 | B36: pcs | C36: Cement Bag 50 kg | I36: -0.6 | K36: Foundation | L36: Cement | M36: =37500/3700/1.18 -> 8.5890976 | N36: =J36*$D$19/(8*60) -> 0 | O36: =M36+N36 -> 8.5890976 | P36: =A36*O36 -> 54.111315
A37: =sumif('Structures Database'!B:B,C37,'Structures Database'!W:W) -> 0.63 | B37: tonnes | C37: Sand per tonne | K37: Foundation | L37: Anchor | M37: =135000/3/3700 -> 12.162162 | N37: =J37*$D$19/(8*60) -> 0 | O37: =M37+N37 -> 12.162162 | P37: =A37*O37 -> 7.6621622
A38: =sumif('Structures Database'!B:B,C38,'Structures Database'!W:W) -> 0.84 | B38: tonnes | C38: Aggregates per tonne | K38: Foundation | L38: Anchor | M38: =230000/3700 -> 62.162162 | N38: =J38*$D$19/(8*60) -> 0 | O38: =M38+N38 -> 62.162162 | P38: =A38*O38 -> 52.216216
A39: =sumif('Structures Database'!B:B,C39,'Structures Database'!W:W) -> 84 | B39: pcs | C39: M12 rod 200 mm (stainless steel) | D39: 16 | F39: 250 | G39: =(D39/2)^2*PI()*F39/1000000000 -> 5.0265482e-05 | K39: Foundation | L39: Rod | M39: 3 | N39: =J39*$D$19/(8*60) -> 0 | O39: =M39+N39 -> 3 | P39: =A39*O39 -> 252
A40: =sumif('Structures Database'!B:B,C40,'Structures Database'!W:W) -> 168 | B40: pcs | C40: M12 nut (stainless steel) | D40: 24 | E40: 24 | F40: 13 | K40: Foundation | L40: Nut | M40: 0.4 | N40: =J40*$D$19/(8*60) -> 0 | O40: =M40+N40 -> 0.4 | P40: =A40*O40 -> 67.2
A41: =sumif('Structures Database'!B:B,C41,'Structures Database'!W:W) -> 168 | B41: pcs | C41: M12 washer (stainless steel) | D41: 30 | F41: 3 | K41: Foundation | L41: Washer | M41: 0.2 | N41: =J41*$D$19/(8*60) -> 0 | O41: =M41+N41 -> 0.2 | P41: =A41*O41 -> 33.6
A42: =sumif('Structures Database'!B:B,C42,'Structures Database'!W:W) -> 84 | B42: pcs | C42: M12 drop anchor | D42: 20 | F42: 65 | K42: Foundation | L42: Anchor | M42: 1 | N42: =J42*$D$19/(8*60) -> 0 | O42: =M42+N42 -> 1 | P42: =A42*O42 -> 84
A43: =sumif('Structures Database'!B:B,C43,'Structures Database'!W:W) -> 2.1 | B43: pcs | C43: Y12 bar 12 metres | D43: 12 | F43: 12000 | G43: =(D43/2)^2*PI()*F43/1000000000 -> 0.001357168 | K43: Foundation | L43: Rebar | M43: =45000/1.18/3700 -> 10.306917 | N43: =J43*$D$19/(8*60) -> 0 | O43: =M43+N43 -> 10.306917 | P43: =A43*O43 -> 21.644526
A44: =sumif('Structures Database'!B:B,C44,'Structures Database'!W:W) -> 2.1 | B44: pcs | C44: 8 mm rebar 12 metres | D44: 8 | F44: 12000 | G44: =(D44/2)^2*PI()*F44/1000000000 -> 0.00060318579 | K44: Foundation | L44: Rebar | M44: =12000/1.18/3700 -> 2.7485112 | N44: =J44*$D$19/(8*60) -> 0 | O44: =M44+N44 -> 2.7485112 | P44: =A44*O44 -> 5.7718736
...

Sheet Timber Order
A3: Timber Procurement Order List
A4: Order date: | B4: Date
A5: By: | B5: Wolf Bierens - Easy Housing
A6: For: | B6: Contact Name - Company
A9: Timber quality and sustainability criteria
A10: Timber must be well seasoned, kiln dried, at specified dimensions within 2-3 mm tolerance and CCA treated. T&G, decking and shiplap planks must be planed and profiled properly.
A11: Timber must be sustainably sourced. This means with FSC (controlled) certification or under EUTR regulation.
A12: Easy Housing holds the legal claim to the construction stored carbon credits realised through its buildings. These credits do not conflict with any REDD+ or comparable forest conservation credits.
A14: Timber orderlist | D14: Specifications
A15: # | B15: Unit | C15: Item | D15: Width (mm) | E15: Height (mm) | F15: Length (mm) | G15: Volume (m3) | H15: Volume total | J15: Weight (kg) | K15: Carbon storage (kg CO2) | L15: Structure | M15: Type
A16: =roundup(sumif('Bill of Quantities'!X:X,C16,'Bill of Quantities'!Z:Z),0) -> 90 | B16: pcs | C16: =L16&" "&M16&" "&D16&" x "&E16&" x "&F16 -> Wall Beam 46 x 71 x 2450 | D16: 46 | E16: 71 | F16: 2450 | G16: =D16*E16*F16*0.000000001 -> 0.0080017 | H16: =A16*G16 -> 0.720153 | J16: =G16*'Bill of Quantities'!$D$16 -> 4.4889537 | K16: =G16*'Bill of Quantities'!$D$18*'Bill of Quantities'!$D$20 -> 7.2308882 | L16: Wall | M16: Beam
A17: =roundup(sumif('Bill of Quantities'!X:X,C17,'Bill of Quantities'!Z:Z),0) -> 103 | B17: pcs | C17: =L17&" "&M17&" "&D17&" x "&E17&" x "&F17 -> Wall Beam 46 x 71 x 3650 | D17: 46 | E17: 71 | F17: 3650 | G17: =D17*E17*F17*0.000000001 -> 0.0119209 | H17: =A17*G17 -> 1.2278527 | J17: =G17*'Bill of Quantities'!$D$16 -> 6.6876249 | K17: =G17*'Bill of Quantities'!$D$18*'Bill of Quantities'!$D$20 -> 10.772548 | L17: Wall | M17: Beam
A18: =roundup(sumif('Bill of Quantities'!X:X,C18,'Bill of Quantities'!Z:Z),0) -> 38 | B18: pcs | C18: =L18&" "&M18&" "&D18&" x "&E18&" x "&F18 -> Roof Beam 46 x 96 x 2450 | D18: 46 | E18: 96 | F18: 2450 | G18: =D18*E18*F18*0.000000001 -> 0.0108192 | H18: =A18*G18 -> 0.4111296 | J18: =G18*'Bill of Quantities'!$D$16 -> 6.0695712 | K18: =G18*'Bill of Quantities'!$D$18*'Bill of Quantities'!$D$20 -> 9.7769756 | L18: Roof | M18: Beam
A19: =roundup(sumif('Bill of Quantities'!X:X,C19,'Bill of Quantities'!Z:Z),0) -> 0 | B19: pcs | C19: =L19&" "&M19&" "&D19&" x "&E19&" x "&F19 -> Roof Beam 46 x 96 x 4250 | D19: 46 | E19: 96 | F19: 4250 | G19: =D19*E19*F19*0.000000001 -> 0.018768 | H19: =A19*G19 -> 0 | J19: =G19*'Bill of Quantities'!$D$16 -> 10.528848 | K19: =G19*'Bill of Quantities'!$D$18*'Bill of Quantities'!$D$20 -> 16.96006 | L19: Roof | M19: Beam
A20: =roundup(sumif('Bill of Quantities'!X:X,C20,'Bill of Quantities'!Z:Z),0) -> 34 | B20: pcs | C20: =L20&" "&M20&" "&D20&" x "&E20&" x "&F20 -> Roof Beam 46 x 96 x 5750 | D20: 46 | E20: 96 | F20: 5750 | G20: =D20*E20*F20*0.000000001 -> 0.025392 | H20: =A20*G20 -> 0.863328 | J20: =G20*'Bill of Quantities'!$D$16 -> 14.244912 | K20: =G20*'Bill of Quantities'!$D$18*'Bill of Quantities'!$D$20 -> 22.945963 | L20: Roof | M20: Beam
A21: =roundup(sumif('Bill of Quantities'!X:X,C21,'Bill of Quantities'!Z:Z),0) -> 86 | B21: pcs | C21: =L21&" "&M21&" "&D21&" x "&E21&" x "&F21 -> Floor Beam 46 x 146 x 2450 | D21: 46 | E21: 146 | F21: 2450 | G21: =D21*E21*F21*0.000000001 -> 0.0164542 | H21: =A21*G21 -> 1.4150612 | J21: =G21*'Bill of Quantities'!$D$16 -> 9.2308062 | K21: =G21*'Bill of Quantities'!$D$18*'Bill of Quantities'!$D$20 -> 14.86915 | L21: Floor | M21: Beam
A22: =roundup(sumif('Bill of Quantities'!X:X,C22,'Bill of Quantities'!Z:Z),0) -> 0 | B22: pcs | C22: =L22&" "&M22&" "&D22&" x "&E22&" x "&F22 -> Floor Beam 46 x 146 x 3050 | D22: 46 | E22: 146 | F22: 3050 | G22: =D22*E22*F22*0.000000001 -> 0.0204838 | H22: =A22*G22 -> 0 | J22: =G22*'Bill of Quantities'!$D$16 -> 11.491412 | K22: =G22*'Bill of Quantities'!$D$18*'Bill of Quantities'!$D$20 -> 18.510575 | L22: Floor | M22: Beam
A23: =roundup(sumif('Bill of Quantities'!X:X,C23,'Bill of Quantities'!Z:Z),0) -> 0 | B23: pcs | C23: =L23&" "&M23&" "&D23&" x "&E23&" x "&F23 -> Floor Beam 46 x 146 x 5450 | D23: 46 | E23: 146 | F23: 5450 | G23: =D23*E23*F23*0.000000001 -> 0.0366022 | H23: =A23*G23 -> 0 | J23: =G23*'Bill of Quantities'!$D$16 -> 20.533834 | K23: =G23*'Bill of Quantities'!$D$18*'Bill of Quantities'!$D$20 -> 33.076273 | L23: Floor | M23: Beam
A24: =roundup(sumif('Bill of Quantities'!X:X,C24,'Bill of Quantities'!Z:Z),0) -> 0 | B24: pcs | C24: =L24&" "&M24&" "&D24&" x "&E24&" x "&F24 -> Timber Column 100 x 100 x 3050 | D24: 100 | E24: 100 | F24: 3050 | G24: =D24*E24*F24*0.000000001 -> 0.0305 | H24: =A24*G24 -> 0 | J24: =G24*'Bill of Quantities'!$D$16 -> 17.1105 | K24: =G24*'Bill of Quantities'!$D$18*'Bill of Quantities'!$D$20 -> 27.561905 | L24: Timber | M24: Column
A25: =roundup(sumif('Bill of Quantities'!X:X,C25,'Bill of Quantities'!Z:Z),0) -> 249 | B25: pcs | C25: =L25&" "&M25&" "&D25&" x "&E25&" x "&F25 -> Timber Back Batten 22 x 46 x 2450 | D25: 22 | E25: 46 | F25: 2450 | G25: =D25*E25*F25*0.000000001 -> 0.0024794 | H25: =A25*G25 -> 0.6173706 | J25: =G25*'Bill of Quantities'!$D$16 -> 1.3909434 | K25: =G25*'Bill of Quantities'!$D$18*'Bill of Quantities'!$D$20 -> 2.2405569 | L25: Timber | M25: Back Batten
A26: =roundup(sumif('Bill of Quantities'!X:X,C26,'Bill of Quantities'!Z:Z),0) -> 0 | B26: pcs | C26: =L26&" "&M26&" "&D26&" x "&E26&" x "&F26 -> Timber Back Batten 22 x 46 x 3050 | D26: 22 | E26: 46 | F26: 3050 | G26: =D26*E26*F26*0.000000001 -> 0.0030866 | H26: =A26*G26 -> 0 | J26: =G26*'Bill of Quantities'!$D$16 -> 1.7315826 | K26: =G26*'Bill of Quantities'!$D$18*'Bill of Quantities'!$D$20 -> 2.7892647 | L26: Timber | M26: Back Batten
A27: =roundup(sumif('Bill of Quantities'!X:X,C27,'Bill of Quantities'!Z:Z),0) -> 328 | B27: pcs | C27: =L27&" "&M27&" "&D27&" x "&E27&" x "&F27 -> Timber Floor Plank 22 x 96 x 2450 | D27: 22 | E27: 96 | F27: 2450 | G27: =D27*E27*F27*0.000000001 -> 0.0051744 | H27: =A27*G27 -> 1.6972032 | J27: =G27*'Bill of Quantities'!$D$16 -> 2.9028384 | K27: =G27*'Bill of Quantities'!$D$18*'Bill of Quantities'!$D$20 -> 4.6759449 | L27: Timber | M27: Floor Plank
... A33: =roundup(sumif('Bill of Quantities'!X:X,C33,'Bill of Quantities'!Z:Z),0) -> 36 | B33: pcs | C33: =L33&" "&M33&" "&D33&" x "&E33&" x "&F33 -> Interior Door Beams 50 x 150 x 2450 | D33: 50 | E33: 150 | F33: 2450 | G33: =D33*E33*F33*0.000000001 -> 0.018375 | H33: =A33*G33 -> 0.6615 | J33: =G33*'Bill of Quantities'!$D$16 -> 10.308375 | K33: =G33*'Bill of Quantities'!$D$18*'Bill of Quantities'!$D$20 -> 16.604918 | L33: Interior Door | M33: Beams
A35: Total amounts | H35: =SUM(H16:H34) -> 10.780124 | I35: cbm
D44: Timber Standard Lengths
D45: Millimetre * | E45: Feet
D46: 2450 | E46: =round(D46/300,0) -> 8
D47: 2750 | E47: =round(D47/300,0) -> 9
D48: 3050 | E48: =round(D48/300,0) -> 10
D49: 3650 | E49: =round(D49/300,0) -> 12
D50: 3950 | E50: =round(D50/300,0) -> 13
D51: 4250 | E51: =round(D51/300,0) -> 14
D52: 5450 | E52: =round(D52/300,0) -> 18
D53: 5750 | E53: =round(D53/300,0) -> 19
D54: 6050 | E54: =round(D54/300,0) -> 20
D56: * default lengths at Busoga, but 6m not always available

Sheet Input Database
A1: Hier komt een database van inputs met behulp van een macro
A2: Macro knop die automatisch een PDF genereert van de project outputs en dan ook hier de inputs in opslaat
B4: Instructions: Copy Cells B20:B46 and paste special here as values only!
B5: Database
B6: Date
A8: Project input | B8: Project Input Database
A9: Client input
A10: ='Price Calc'!A13 -> Client Name | B10: One Bed Mono | C10: John's | D10: Alex Michael Thiaka | E10: Ziwa Rhino Sanctuary | F10: Tamsin Scurfield | G10: Jesse & Naomi | H10: Maureen | I10: Tamsin test | J10: Soul Agri Business Company Ltd | K10: Anwar
A11: ='Price Calc'!A14 -> Contact Details | B11: Example | C11: Test | D11: bolossatestates@gmail.com | E11: Captain Joe Roy | F11: tamsaway@gmail.com | G11: nduksk@gmail.com | H11: 254 722 808352 | I11: 0 | J11: +256 759 740888 | K11: +256 759 740888
A12: ='Price Calc'!A23 -> Project Location | B12: Greater Kampala | C12: Greater Kampala | D12: Olkalau | E12: Ziwa | F12: Jinja | G12: Nairobi | H12: Nairobi | I12: Kampala | J12: Kiryandongo | K12: Kiryandongo
A13: ='Price Calc'!A24 -> Distance from factory | B13: 50 | C13: 50 | D13: 150 | E13: 177 | F13: 89 | G13: 50 | H13: 180 | I13: 150 | J13: 213 | K13: 213
A14: Date of input
A15: ='Price Calc'!A15 -> Created by | B15: Wolf Bierens | C15: Wolf Bierens | D15: Monicah Migwi | E15: Wolf Bierens | F15: Brian Kulubya | G15: Wolf Bierens | H15: Branton | I15: Wolf | J15: Aaron | K15: Aaron
A17: Building input (structure parameters)
A18: ='Price Calc'!A18 -> Easy Housing Typology | B18: Mono Pitch | C18: Compact Gable | D18: Large Clerestory | E18: Compact Gable | F18: Large Clerestory | G18: Large Clerestory | H18: Mono Pitch | I18: Large Clerestory | J18: Large Clerestory | K18: Compact Gable
A19: Number of units (of exactly this type) | B19: 1 | C19: 1 | D19: 1 | E19: 4 | F19: 1 | G19: 1 | H19: 1 | I19: 1 | J19: 1 | K19: 1
A20: ='Price Calc'!A59 -> Columns A (1221) | B20: 0 | C20: 0 | D20: 2 | E20: 0 | F20: 2 | G20: 2 | H20: 0 | I20: 2 | J20: 3 | K20: 0
A21: ='Price Calc'!A60 -> Columns B (2442) | B21: 3 | C21: 4 | D21: 4 | E21: 4 | F21: 0 | G21: 2 | H21: 2 | I21: 2 | J21: 0 | K21: 4
A22: ='Price Calc'!A61 -> Columns C (3053) | B22: 0 | C22: 0 | D22: 0 | E22: 0 | F22: 2 | G22: 1 | H22: 3 | I22: 0 | J22: 3 | K22: 0
A23: ='Price Calc'!A64 -> Interior doors | B23: 2 | C23: 4 | D23: 6 | E23: 2 | F23: 3 | G23: 5 | H23: 4 | I23: 3 | J23: 1 | K23: 4
A24: ='Price Calc'!A65 -> Partitions (length) | B24: 6 | C24: 19.5 | D24: 37.7 | E24: 9 | F24: 15 | G24: 32 | H24: 6 | I24: 16 | J24: 39 | K24: 18.2
A25: ='Price Calc'!A66 -> Exterior doors & windows (area) | B25: 7.9 | C25: 15 | D25: 28.8 | E25: 22 | F25: 30.3 | G25: 27.2 | H25: 9.4 | I25: 23.3 | J25: 27 | K25: 14.7
A26: Bedrooms | B26: 1 | C26: 2 | D26: 3 | E26: 2 | F26: 2 | G26: 3 | H26: 3 | I26: 2 | J26: 4 | K26: 2
A27: Bathrooms | B27: 1 | C27: 2 | D27: 4 | E27: 1 | F27: 1 | G27: 2 | H27: 2 | I27: 1 | J27: 4 | K27: 2
A28: Kitchen areas | B28: 1 | C28: 1 | D28: 1 | E28: 0 | F28: 0 | G28: 1 | H28: 1 | I28: 1 | J28: 1 | K28: 1
A30: Additional options
A31: ='Price Calc'!A41 -> Terrace | B31: 0 | C31: 6 | D31: 18.5 | E31: 4 | F31: 27 | G31: 19 | H31: 4 | I31: 25.8 | J31: 11 | K31: 0
A32: ='Price Calc'!A42 -> Pergola | B32: 0 | C32: 6 | D32: 18.5 | E32: 0 | F32: 27 | G32: 17 | H32: 4 | I32: 25.8 | J32: 11 | K32: 0
A33: ='Price Calc'!A43 -> Railing open | B33: 0 | C33: 0 | D33: 11 | E33: 0 | F33: 14.7 | G33: 17 | H33: 0 | I33: 13 | J33: 0 | K33: 0
A34: ='Price Calc'!A44 -> Railing semi-closed | B34: 0 | C34: 0 | D34: 0 | E34: 10 | F34: 0 | G34: 0 | H34: 0 | I34: 0 | J34: 0 | K34: 0
A35: ='Price Calc'!A67 -> Extra staircase (beyond the first) | B35: 0 | C35: 0 | D35: 1 | E35: 0 | F35: 1 | G35: 1 | H35: 0 | I35: 0 | J35: 0 | K35: 0
A36: ='Price Calc'!A40 -> Burglar bars | B36: 0 | C36: 10 | D36: 0 | E36: 0 | F36: 0 | G36: 0 | H36: 0 | I36: 0 | J36: 0 | K36: 0
A37: ='Price Calc'!A45 -> Wheelchair ramp | B37: 0 | C37: 0 | D37: 0 | E37: 0 | F37: 0 | G37: 0 | H37: 0 | I37: 0 | J37: 0 | K37: 0
A38: ='Price Calc'!A46 -> Tiles | B38: 0 | C38: 0 | D38: 0 | E38: 1350000 | F38: 1500000 | G38: 0 | H38: 0 | I38: 2000000 | J38: 6400000 | K38: 0
A39: ='Price Calc'!A47 -> Sanitary wares | B39: 0 | C39: 0 | D39: 0 | E39: 2800000 | F39: 3500000 | G39: 0 | H39: 0 | I39: 3000000 | J39: 14000000 | K39: 0
A40: ='Price Calc'!A48 -> Biodigester | B40: 0 | C40: 0 | D40: 0 | E40: 0 | F40: 3100000 | G40: 0 | H40: 0 | I40: 3000000 | J40: 3200000 | K40: 0
A41: Other option(s) description | F41: Foundation extra height | G41: Foundation height at 1.2m | J41: Kitchen
A42: Other option(s) price | F42: 2500000 | G42: 150000 | J42: 5000000
K48: Amount
K49: 0
...

Sheet Structures Database
A1: Structures database | C1: Per element | L1: Project cost item | O1: Totals per frame | V1: Calculation columns for building input
A2: # | B2: Element name | C2: ='Bill of Quantities'!D2 -> Width (mm) | D2: ='Bill of Quantities'!E2 -> Height (mm) | E2: ='Bill of Quantities'!F2 -> Length (mm) | F2: ='Bill of Quantities'!G2 -> Volume (m3) | G2: ='Bill of Quantities'!H2 -> Weight (kg) | H2: ='Bill of Quantities'!I2 -> Carbon storage (kg CO2) | I2: ='Bill of Quantities'!J2 -> Labour (min) | J2: ='Bill of Quantities'!K2 -> Structure | ... N2: ='Bill of Quantities'!O2 -> Total cost ($) | O2: Volume (m3) | P2: Weight (kg) | Q2: =H2 -> Carbon storage (kg CO2) | R2: =I2 -> Labour (min) | S2: =L2 -> Item cost ($) | T2: =M2 -> Labour cost ($) | U2: =N2 -> Total cost ($) | V2: Frame name | W2: Items in building | X2: Labour hours | Y2: Surface per frame
A4: Floor frames
A6: Foundation point | V6: =V7 -> Foundation point | Y6: =C6*E6*0.000001 -> 0
A7: 1 | B7: ='Bill of Quantities'!C35 -> Foundation block | C7: {=index('Bill of Quantities'!$D:$O,match($B7,'Bill of Quantities'!$C:$C,0),match(C$2,'Bill of Quantities'!$D$2:$O$2,0))} -> 300 | D7: {=index('Bill of Quantities'!$D:$O,match($B7,'Bill of Quantities'!$C:$C,0),match(D$2,'Bill of Quantities'!$D$2:$O$2,0))} -> 400 | E7: {=index('Bill of Quantities'!$D:$O,match($B7,'Bill of Quantities'!$C:$C,0),match(E$2,'Bill of Quantities'!$D$2:$O$2,0))} -> 300 | F7: {=index('Bill of Quantities'!$D:$O,match($B7,'Bill of Quantities'!$C:$C,0),match(F$2,'Bill of Quantities'!$D$2:$O$2,0))} -> 0.036 | G7: {=index('Bill of Quantities'!$D:$O,match($B7,'Bill of Quantities'!$C:$C,0),match(G$2,'Bill of Quantities'!$D$2:$O$2,0))} -> 86.4 | H7: {=index('Bill of Quantities'!$D:$O,match($B7,'Bill of Quantities'!$C:$C,0),match(H$2,'Bill of Quantities'!$D$2:$O$2,0))} -> 0 | I7: {=index('Bill of Quantities'!$D:$O,match($B7,'Bill of Quantities'!$C:$C,0),match(I$2,'Bill of Quantities'!$D$2:$O$2,0))} -> 180 | J7: {=index('Bill of Quantities'!$D:$O,match($B7,'Bill of Quantities'!$C:$C,0),match(J$2,'Bill of Quantities'!$D$2:$O$2,0))} -> Foundation | ... N7: {=index('Bill of Quantities'!$D:$O,match($B7,'Bill of Quantities'!$C:$C,0),match(N$2,'Bill of Quantities'!$D$2:$O$2,0))} -> 5.625 | O7: =$A7*F7 -> 0.036 | P7: =$A7*G7 -> 86.4 | Q7: =$A7*H7 -> 0 | R7: =$A7*I7 -> 180 | S7: =$A7*L7 -> 0 | T7: =$A7*M7 -> 5.625 | U7: =$A7*N7 -> 5.625 | V7: =$A$6 -> Foundation point | W7: {=A7*index('Project Costs'!A:A,match(V7,'Project Costs'!B:B,0),1)} -> 21 | X7: =W7*R7/60 -> 63
A8: 0.3 | B8: ='Bill of Quantities'!C36 -> Cement Bag 50 kg | C8: {=index('Bill of Quantities'!$D:$O,match($B8,'Bill of Quantities'!$C:$C,0),match(C$2,'Bill of Quantities'!$D$2:$O$2,0))} | D8: {=index('Bill of Quantities'!$D:$O,match($B8,'Bill of Quantities'!$C:$C,0),match(D$2,'Bill of Quantities'!$D$2:$O$2,0))} | E8: {=index('Bill of Quantities'!$D:$O,match($B8,'Bill of Quantities'!$C:$C,0),match(E$2,'Bill of Quantities'!$D$2:$O$2,0))} | F8: {=index('Bill of Quantities'!$D:$O,match($B8,'Bill of Quantities'!$C:$C,0),match(F$2,'Bill of Quantities'!$D$2:$O$2,0))} | G8: {=index('Bill of Quantities'!$D:$O,match($B8,'Bill of Quantities'!$C:$C,0),match(G$2,'Bill of Quantities'!$D$2:$O$2,0))} | H8: {=index('Bill of Quantities'!$D:$O,match($B8,'Bill of Quantities'!$C:$C,0),match(H$2,'Bill of Quantities'!$D$2:$O$2,0))} -> -0.6 | I8: {=index('Bill of Quantities'!$D:$O,match($B8,'Bill of Quantities'!$C:$C,0),match(I$2,'Bill of Quantities'!$D$2:$O$2,0))} | J8: {=index('Bill of Quantities'!$D:$O,match($B8,'Bill of Quantities'!$C:$C,0),match(J$2,'Bill of Quantities'!$D$2:$O$2,0))} -> Foundation | ... N8: {=index('Bill of Quantities'!$D:$O,match($B8,'Bill of Quantities'!$C:$C,0),match(N$2,'Bill of Quantities'!$D$2:$O$2,0))} -> 8.5890976 | O8: =$A8*F8 -> 0 | P8: =$A8*G8 -> 0 | Q8: =$A8*H8 -> -0.18 | R8: =$A8*I8 -> 0 | S8: =$A8*L8 -> 2.5767293 | T8: =$A8*M8 -> 0 | U8: =$A8*N8 -> 2.5767293 | V8: =$A$6 -> Foundation point | W8: {=A8*index('Project Costs'!A:A,match(V8,'Project Costs'!B:B,0),1)} -> 6.3 | X8: =W8*R8/60 -> 0
A9: =30/1000 -> 0.03 | B9: ='Bill of Quantities'!C37 -> Sand per tonne | C9: {=index('Bill of Quantities'!$D:$O,match($B9,'Bill of Quantities'!$C:$C,0),match(C$2,'Bill of Quantities'!$D$2:$O$2,0))} | D9: {=index('Bill of Quantities'!$D:$O,match($B9,'Bill of Quantities'!$C:$C,0),match(D$2,'Bill of Quantities'!$D$2:$O$2,0))} | E9: {=index('Bill of Quantities'!$D:$O,match($B9,'Bill of Quantities'!$C:$C,0),match(E$2,'Bill of Quantities'!$D$2:$O$2,0))} | F9: {=index('Bill of Quantities'!$D:$O,match($B9,'Bill of Quantities'!$C:$C,0),match(F$2,'Bill of Quantities'!$D$2:$O$2,0))} | G9: {=index('Bill of Quantities'!$D:$O,match($B9,'Bill of Quantities'!$C:$C,0),match(G$2,'Bill of Quantities'!$D$2:$O$2,0))} | H9: {=index('Bill of Quantities'!$D:$O,match($B9,'Bill of Quantities'!$C:$C,0),match(H$2,'Bill of Quantities'!$D$2:$O$2,0))} | I9: {=index('Bill of Quantities'!$D:$O,match($B9,'Bill of Quantities'!$C:$C,0),match(I$2,'Bill of Quantities'!$D$2:$O$2,0))} | J9: {=index('Bill of Quantities'!$D:$O,match($B9,'Bill of Quantities'!$C:$C,0),match(J$2,'Bill of Quantities'!$D$2:$O$2,0))} -> Foundation | ... N9: {=index('Bill of Quantities'!$D:$O,match($B9,'Bill of Quantities'!$C:$C,0),match(N$2,'Bill of Quantities'!$D$2:$O$2,0))} -> 12.162162 | O9: =$A9*F9 -> 0 | P9: =$A9*G9 -> 0 | Q9: =$A9*H9 -> 0 | R9: =$A9*I9 -> 0 | S9: =$A9*L9 -> 0.36486486 | T9: =$A9*M9 -> 0 | U9: =$A9*N9 -> 0.36486486 | V9: =$A$6 -> Foundation point | W9: {=A9*index('Project Costs'!A:A,match(V9,'Project Costs'!B:B,0),1)} -> 0.63 | X9: =W9*R9/60 -> 0
A10: =40/1000 -> 0.04 | B10: ='Bill of Quantities'!C38 -> Aggregates per tonne | C10: {=index('Bill of Quantities'!$D:$O,match($B10,'Bill of Quantities'!$C:$C,0),match(C$2,'Bill of Quantities'!$D$2:$O$2,0))} | D10: {=index('Bill of Quantities'!$D:$O,match($B10,'Bill of Quantities'!$C:$C,0),match(D$2,'Bill of Quantities'!$D$2:$O$2,0))} | E10: {=index('Bill of Quantities'!$D:$O,match($B10,'Bill of Quantities'!$C:$C,0),match(E$2,'Bill of Quantities'!$D$2:$O$2,0))} | F10: {=index('Bill of Quantities'!$D:$O,match($B10,'Bill of Quantities'!$C:$C,0),match(F$2,'Bill of Quantities'!$D$2:$O$2,0))} | G10: {=index('Bill of Quantities'!$D:$O,match($B10,'Bill of Quantities'!$C:$C,0),match(G$2,'Bill of Quantities'!$D$2:$O$2,0))} | H10: {=index('Bill of Quantities'!$D:$O,match($B10,'Bill of Quantities'!$C:$C,0),match(H$2,'Bill of Quantities'!$D$2:$O$2,0))} | I10: {=index('Bill of Quantities'!$D:$O,match($B10,'Bill of Quantities'!$C:$C,0),match(I$2,'Bill of Quantities'!$D$2:$O$2,0))} | J10: {=index('Bill of Quantities'!$D:$O,match($B10,'Bill of Quantities'!$C:$C,0),match(J$2,'Bill of Quantities'!$D$2:$O$2,0))} -> Foundation | ... N10: {=index('Bill of Quantities'!$D:$O,match($B10,'Bill of Quantities'!$C:$C,0),match(N$2,'Bill of Quantities'!$D$2:$O$2,0))} -> 62.162162 | O10: =$A10*F10 -> 0 | P10: =$A10*G10 -> 0 | Q10: =$A10*H10 -> 0 | R10: =$A10*I10 -> 0 | S10: =$A10*L10 -> 2.4864865 | T10: =$A10*M10 -> 0 | U10: =$A10*N10 -> 2.4864865 | V10: =$A$6 -> Foundation point | W10: {=A10*index('Project Costs'!A:A,match(V10,'Project Costs'!B:B,0),1)} -> 0.84 | X10: =W10*R10/60 -> 0
A11: 4 | B11: ='Bill of Quantities'!C39 -> M12 rod 200 mm (stainless steel) | C11: {=index('Bill of Quantities'!$D:$O,match($B11,'Bill of Quantities'!$C:$C,0),match(C$2,'Bill of Quantities'!$D$2:$O$2,0))} -> 16 | D11: {=index('Bill of Quantities'!$D:$O,match($B11,'Bill of Quantities'!$C:$C,0),match(D$2,'Bill of Quantities'!$D$2:$O$2,0))} | E11: {=index('Bill of Quantities'!$D:$O,match($B11,'Bill of Quantities'!$C:$C,0),match(E$2,'Bill of Quantities'!$D$2:$O$2,0))} -> 250 | F11: {=index('Bill of Quantities'!$D:$O,match($B11,'Bill of Quantities'!$C:$C,0),match(F$2,'Bill of Quantities'!$D$2:$O$2,0))} -> 5.0265482e-05 | G11: {=index('Bill of Quantities'!$D:$O,match($B11,'Bill of Quantities'!$C:$C,0),match(G$2,'Bill of Quantities'!$D$2:$O$2,0))} | H11: {=index('Bill of Quantities'!$D:$O,match($B11,'Bill of Quantities'!$C:$C,0),match(H$2,'Bill of Quantities'!$D$2:$O$2,0))} | I11: {=index('Bill of Quantities'!$D:$O,match($B11,'Bill of Quantities'!$C:$C,0),match(I$2,'Bill of Quantities'!$D$2:$O$2,0))} | J11: {=index('Bill of Quantities'!$D:$O,match($B11,'Bill of Quantities'!$C:$C,0),match(J$2,'Bill of Quantities'!$D$2:$O$2,0))} -> Foundation | ... N11: {=index('Bill of Quantities'!$D:$O,match($B11,'Bill of Quantities'!$C:$C,0),match(N$2,'Bill of Quantities'!$D$2:$O$2,0))} -> 3 | O11: =$A11*F11 -> 0.00020106193 | P11: =$A11*G11 -> 0 | Q11: =$A11*H11 -> 0 | R11: =$A11*I11 -> 0 | S11: =$A11*L11 -> 12 | T11: =$A11*M11 -> 0 | U11: =$A11*N11 -> 12 | V11: =$A$6 -> Foundation point | W11: {=A11*index('Project Costs'!A:A,match(V11,'Project Costs'!B:B,0),1)} -> 84 | X11: =W11*R11/60 -> 0
A12: 8 | B12: ='Bill of Quantities'!C40 -> M12 nut (stainless steel) | C12: {=index('Bill of Quantities'!$D:$O,match($B12,'Bill of Quantities'!$C:$C,0),match(C$2,'Bill of Quantities'!$D$2:$O$2,0))} -> 24 | D12: {=index('Bill of Quantities'!$D:$O,match($B12,'Bill of Quantities'!$C:$C,0),match(D$2,'Bill of Quantities'!$D$2:$O$2,0))} -> 24 | E12: {=index('Bill of Quantities'!$D:$O,match($B12,'Bill of Quantities'!$C:$C,0),match(E$2,'Bill of Quantities'!$D$2:$O$2,0))} -> 13 | F12: {=index('Bill of Quantities'!$D:$O,match($B12,'Bill of Quantities'!$C:$C,0),match(F$2,'Bill of Quantities'!$D$2:$O$2,0))} | G12: {=index('Bill of Quantities'!$D:$O,match($B12,'Bill of Quantities'!$C:$C,0),match(G$2,'Bill of Quantities'!$D$2:$O$2,0))} | H12: {=index('Bill of Quantities'!$D:$O,match($B12,'Bill of Quantities'!$C:$C,0),match(H$2,'Bill of Quantities'!$D$2:$O$2,0))} | I12: {=index('Bill of Quantities'!$D:$O,match($B12,'Bill of Quantities'!$C:$C,0),match(I$2,'Bill of Quantities'!$D$2:$O$2,0))} | J12: {=index('Bill of Quantities'!$D:$O,match($B12,'Bill of Quantities'!$C:$C,0),match(J$2,'Bill of Quantities'!$D$2:$O$2,0))} -> Foundation | ... N12: {=index('Bill of Quantities'!$D:$O,match($B12,'Bill of Quantities'!$C:$C,0),match(N$2,'Bill of Quantities'!$D$2:$O$2,0))} -> 0.4 | O12: =$A12*F12 -> 0 | P12: =$A12*G12 -> 0 | Q12: =$A12*H12 -> 0 | R12: =$A12*I12 -> 0 | S12: =$A12*L12 -> 3.2 | T12: =$A12*M12 -> 0 | U12: =$A12*N12 -> 3.2 | V12: =$A$6 -> Foundation point | W12: {=A12*index('Project Costs'!A:A,match(V12,'Project Costs'!B:B,0),1)} -> 168 | X12: =W12*R12/60 -> 0
A13: 8 | B13: ='Bill of Quantities'!C41 -> M12 washer (stainless steel) | C13: {=index('Bill of Quantities'!$D:$O,match($B13,'Bill of Quantities'!$C:$C,0),match(C$2,'Bill of Quantities'!$D$2:$O$2,0))} -> 30 | D13: {=index('Bill of Quantities'!$D:$O,match($B13,'Bill of Quantities'!$C:$C,0),match(D$2,'Bill of Quantities'!$D$2:$O$2,0))} | E13: {=index('Bill of Quantities'!$D:$O,match($B13,'Bill of Quantities'!$C:$C,0),match(E$2,'Bill of Quantities'!$D$2:$O$2,0))} -> 3 | F13: {=index('Bill of Quantities'!$D:$O,match($B13,'Bill of Quantities'!$C:$C,0),match(F$2,'Bill of Quantities'!$D$2:$O$2,0))} | G13: {=index('Bill of Quantities'!$D:$O,match($B13,'Bill of Quantities'!$C:$C,0),match(G$2,'Bill of Quantities'!$D$2:$O$2,0))} | H13: {=index('Bill of Quantities'!$D:$O,match($B13,'Bill of Quantities'!$C:$C,0),match(H$2,'Bill of Quantities'!$D$2:$O$2,0))} | I13: {=index('Bill of Quantities'!$D:$O,match($B13,'Bill of Quantities'!$C:$C,0),match(I$2,'Bill of Quantities'!$D$2:$O$2,0))} | J13: {=index('Bill of Quantities'!$D:$O,match($B13,'Bill of Quantities'!$C:$C,0),match(J$2,'Bill of Quantities'!$D$2:$O$2,0))} -> Foundation | ... N13: {=index('Bill of Quantities'!$D:$O,match($B13,'Bill of Quantities'!$C:$C,0),match(N$2,'Bill of Quantities'!$D$2:$O$2,0))} -> 0.2 | O13: =$A13*F13 -> 0 | P13: =$A13*G13 -> 0 | Q13: =$A13*H13 -> 0 | R13: =$A13*I13 -> 0 | S13: =$A13*L13 -> 1.6 | T13: =$A13*M13 -> 0 | U13: =$A13*N13 -> 1.6 | V13: =$A$6 -> Foundation point | W13: {=A13*index('Project Costs'!A:A,match(V13,'Project Costs'!B:B,0),1)} -> 168 | X13: =W13*R13/60 -> 0
A14: 4 | B14: ='Bill of Quantities'!C42 -> M12 drop anchor | C14: {=index('Bill of Quantities'!$D:$O,match($B14,'Bill of Quantities'!$C:$C,0),match(C$2,'Bill of Quantities'!$D$2:$O$2,0))} -> 20 | D14: {=index('Bill of Quantities'!$D:$O,match($B14,'Bill of Quantities'!$C:$C,0),match(D$2,'Bill of Quantities'!$D$2:$O$2,0))} | E14: {=index('Bill of Quantities'!$D:$O,match($B14,'Bill of Quantities'!$C:$C,0),match(E$2,'Bill of Quantities'!$D$2:$O$2,0))} -> 65 | F14: {=index('Bill of Quantities'!$D:$O,match($B14,'Bill of Quantities'!$C:$C,0),match(F$2,'Bill of Quantities'!$D$2:$O$2,0))} | G14: {=index('Bill of Quantities'!$D:$O,match($B14,'Bill of Quantities'!$C:$C,0),match(G$2,'Bill of Quantities'!$D$2:$O$2,0))} | H14: {=index('Bill of Quantities'!$D:$O,match($B14,'Bill of Quantities'!$C:$C,0),match(H$2,'Bill of Quantities'!$D$2:$O$2,0))} | I14: {=index('Bill of Quantities'!$D:$O,match($B14,'Bill of Quantities'!$C:$C,0),match(I$2,'Bill of Quantities'!$D$2:$O$2,0))} | J14: {=index('Bill of Quantities'!$D:$O,match($B14,'Bill of Quantities'!$C:$C,0),match(J$2,'Bill of Quantities'!$D$2:$O$2,0))} -> Foundation | ... N14: {=index('Bill of Quantities'!$D:$O,match($B14,'Bill of Quantities'!$C:$C,0),match(N$2,'Bill of Quantities'!$D$2:$O$2,0))} -> 1 | O14: =$A14*F14 -> 0 | P14: =$A14*G14 -> 0 | Q14: =$A14*H14 -> 0 | R14: =$A14*I14 -> 0 | S14: =$A14*L14 -> 4 | T14: =$A14*M14 -> 0 | U14: =$A14*N14 -> 4 | V14: =$A$6 -> Foundation point | W14: {=A14*index('Project Costs'!A:A,match(V14,'Project Costs'!B:B,0),1)} -> 84 | X14: =W14*R14/60 -> 0
A15: 0.1 | B15: ='Bill of Quantities'!C43 -> Y12 bar 12 metres | C15: {=index('Bill of Quantities'!$D:$O,match($B15,'Bill of Quantities'!$C:$C,0),match(C$2,'Bill of Quantities'!$D$2:$O$2,0))} -> 12 | D15: {=index('Bill of Quantities'!$D:$O,match($B15,'Bill of Quantities'!$C:$C,0),match(D$2,'Bill of Quantities'!$D$2:$O$2,0))} | E15: {=index('Bill of Quantities'!$D:$O,match($B15,'Bill of Quantities'!$C:$C,0),match(E$2,'Bill of Quantities'!$D$2:$O$2,0))} -> 12000 | F15: {=index('Bill of Quantities'!$D:$O,match($B15,'Bill of Quantities'!$C:$C,0),match(F$2,'Bill of Quantities'!$D$2:$O$2,0))} -> 0.001357168 | G15: {=index('Bill of Quantities'!$D:$O,match($B15,'Bill of Quantities'!$C:$C,0),match(G$2,'Bill of Quantities'!$D$2:$O$2,0))} | H15: {=index('Bill of Quantities'!$D:$O,match($B15,'Bill of Quantities'!$C:$C,0),match(H$2,'Bill of Quantities'!$D$2:$O$2,0))} | I15: {=index('Bill of Quantities'!$D:$O,match($B15,'Bill of Quantities'!$C:$C,0),match(I$2,'Bill of Quantities'!$D$2:$O$2,0))} | J15: {=index('Bill of Quantities'!$D:$O,match($B15,'Bill of Quantities'!$C:$C,0),match(J$2,'Bill of Quantities'!$D$2:$O$2,0))} -> Foundation | ... N15: {=index('Bill of Quantities'!$D:$O,match($B15,'Bill of Quantities'!$C:$C,0),match(N$2,'Bill of Quantities'!$D$2:$O$2,0))} -> 10.306917 | O15: =$A15*F15 -> 0.0001357168 | P15: =$A15*G15 -> 0 | Q15: =$A15*H15 -> 0 | R15: =$A15*I15 -> 0 | S15: =$A15*L15 -> 1.0306917 | T15: =$A15*M15 -> 0 | U15: =$A15*N15 -> 1.0306917 | V15: =$A$6 -> Foundation point | W15: {=A15*index('Project Costs'!A:A,match(V15,'Project Costs'!B:B,0),1)} -> 2.1 | X15: =W15*R15/60 -> 0
A16: 0.1 | B16: ='Bill of Quantities'!C44 -> 8 mm rebar 12 metres | C16: {=index('Bill of Quantities'!$D:$O,match($B16,'Bill of Quantities'!$C:$C,0),match(C$2,'Bill of Quantities'!$D$2:$O$2,0))} -> 8 | D16: {=index('Bill of Quantities'!$D:$O,match($B16,'Bill of Quantities'!$C:$C,0),match(D$2,'Bill of Quantities'!$D$2:$O$2,0))} | E16: {=index('Bill of Quantities'!$D:$O,match($B16,'Bill of Quantities'!$C:$C,0),match(E$2,'Bill of Quantities'!$D$2:$O$2,0))} -> 12000 | F16: {=index('Bill of Quantities'!$D:$O,match($B16,'Bill of Quantities'!$C:$C,0),match(F$2,'Bill of Quantities'!$D$2:$O$2,0))} -> 0.00060318579 | G16: {=index('Bill of Quantities'!$D:$O,match($B16,'Bill of Quantities'!$C:$C,0),match(G$2,'Bill of Quantities'!$D$2:$O$2,0))} | H16: {=index('Bill of Quantities'!$D:$O,match($B16,'Bill of Quantities'!$C:$C,0),match(H$2,'Bill of Quantities'!$D$2:$O$2,0))} | I16: {=index('Bill of Quantities'!$D:$O,match($B16,'Bill of Quantities'!$C:$C,0),match(I$2,'Bill of Quantities'!$D$2:$O$2,0))} | J16: {=index('Bill of Quantities'!$D:$O,match($B16,'Bill of Quantities'!$C:$C,0),match(J$2,'Bill of Quantities'!$D$2:$O$2,0))} -> Foundation | ... N16: {=index('Bill of Quantities'!$D:$O,match($B16,'Bill of Quantities'!$C:$C,0),match(N$2,'Bill of Quantities'!$D$2:$O$2,0))} -> 2.7485112 | O16: =$A16*F16 -> 6.0318579e-05 | P16: =$A16*G16 -> 0 | Q16: =$A16*H16 -> 0 | R16: =$A16*I16 -> 0 | S16: =$A16*L16 -> 0.27485112 | T16: =$A16*M16 -> 0 | U16: =$A16*N16 -> 0.27485112 | V16: =$A$6 -> Foundation point | W16: {=A16*index('Project Costs'!A:A,match(V16,'Project Costs'!B:B,0),1)} -> 2.1 | X16: =W16*R16/60 -> 0
