Workbook

Sheet Project Input
A1: Easy Housing - Calculation Template - 2026 | B1: Last update: 22-06-2026 by Wolf
A3: Instructions
A4: Open floor plan (.pdf) for which quote has to be made
A5: Fill out the input fields below
A6: Check if parameters like floor area correspond with plan
A7: Open Google Slide: "Easy Housing - Quotation Template Uganda - July 2025"
A8: Update the two tables in the slide
A9: Check if quotation values are properly linked to the template
A10: Do not adjust text or fields in slide template
A11: Create a copy of Google slide doc quote template (from the right country)
A12: Copy the input column in this spreadsheet to the Input Database from column K onwards (for future reference)
A13: Download Google Slide as .pdf and save in the shared quotation folder on the drive
A14: File name format: "YYMMDD - Easy Housing Quotation - Client Name in Location"
... A17: Sign the contract! :)
A20: Project input | B20: Input values | C20: Unit | D20: Comment
A21: Client input
A22: ='Price Calc'!A13 -> Client Name | B22: One Bedroom Compact Gable | C22: name | D22: Full name
A23: ='Price Calc'!A14 -> Contact Details | B23: +256 712 345 678 | C23: phone/mail | D23: Add phone or email
A24: ='Price Calc'!A23 -> Project Location | B24: Sagala | C24: location | D24: Add name municipality (village/town/city)
A25: ='Price Calc'!A24 -> Distance from factory | B25: 50 | C25: km | D25: With Google maps
A26: Date of input | B26: 46023 | C26: date | D26: DD/MM/YYYY
A27: ='Price Calc'!A15 -> Created by | B27: Wolf Bierens | C27: name | D27: Add your full name
A29: Building input (structure parameters)
A30: ='Price Calc'!A18 -> Easy Housing Typology | B30: Large Gable (9768) | D30: Select right typology (mm depth of building between brackets to check if not sure)
A31: Number of units (of exactly this type) | B31: 1 | C31: home(s) | D31: Make separate quotes for different models / plans
A32: ='Price Calc'!A60 -> Columns A (1221) | B32: 0 | C32: columns
A33: ='Price Calc'!A61 -> Columns B (2442) | B33: 2 | C33: columns
A34: ='Price Calc'!A62 -> Columns C (3053) | B34: 2 | C34: columns | D34: Do not use for Large A-Frames and Compact Gable | F34: Total GFA | G34: ='Price Calc'!H19 -> 109.2 | H34: sqm (without extra terraces)
A35: ='Price Calc'!A66 -> Partitions (length) | B35: 33 | C35: linear metres | F35: Estimate | G35: =0.3*G34 -> 32.76 | H35: Can be used for quick estimates
A36: ='Price Calc'!A65 -> Interior doors | B36: 5 | C36: pcs | F36: Estimate | G36: =sum(B38:B40) -> 5 | H36: Default estimations
A37: ='Price Calc'!A67 -> External doors & windows (area) | B37: 23.7 | C37: sqm | D37: Total alu - fill tool below - cell linked to D81 | F37: Estimate | G37: =0.2*'Project Costs'!B27 -> 24.812827
A38: Bedrooms | B38: 3 | C38: number
A39: Bathrooms | B39: 2 | C39: number | D39: Count for plumbing
A40: Other rooms | B40: 0 | C40: number
A41: Kitchen areas | B41: 1 | C41: number | D41: Count for plumbing. Kitchen islands count separately.
A43: Additional options
A44: ='Price Calc'!A41 -> Terrace | B44: 0 | C44: sqm | D44: Inside verandas under roof section are not counted (as they are within typology GFA)
A45: ='Price Calc'!A42 -> Pergola | B45: 0 | C45: sqm | D45: Price for open pergola without sheets
A46: ='Price Calc'!A43 -> Railing open | B46: 0 | C46: linear metres
A47: ='Price Calc'!A44 -> Railing semi-closed | B47: 0 | C47: linear metres
...

Sheet Project Output
J2: HOW TO USE THIS QUOTATION (this column is not printed)
B3: Quotation | J3: 1. Enter the quote details on the Project Input tab — they flow here automatically via Price Calc.
J4: 2. Pick the country in the yellow cell C5 (Uganda = UGX, Kenya = KES). All prices and the currency switch instantly.
B5: Country (select): | C5: Uganda | E5: Quotation date: | F5: =TODAY() -> 46195 | H5: =IF($C$5="Kenya","KES","UGX") -> UGX | J5: 3. Review the client info, building specification and price breakdown.
B6: Quotation ref: | C6: ="EH-"&TEXT(TODAY(),"YYMMDD") -> EH-260622 | E6: Valid until: | F6: =TODAY()+30 -> 46225 | J6: 4. Optional: hide any additional-option rows showing “–” before sending, so the client only sees the included options.
J7: 5. Export to PDF: File ▸ Export As / Save As ▸ PDF (or Ctrl/Cmd+P ▸ Save as PDF). The print area and A4 page setup are preset to fit ~2 pages.
B8: CLIENT INFORMATION | J8: 6. Save with the file name: “YYMMDD - Easy Housing Quotation - Client in Location”, then send it with the floor-plan PDF.
B9: Client name | C9: ='Price Calc'!B13 -> One Bedroom Compact Gable
B10: Contact details | C10: ='Price Calc'!B14 -> +256 712 345 678 | J10: Note on macro buttons: one-click “Save to database” and “Export PDF” buttons need a macro-enabled workbook (.xlsm). This file is a standard .xlsx, so those run as the manual steps above. Ask if you would like an .xlsm version with the buttons wired up.
B11: Project location | C11: ='Price Calc'!B23 -> Sagala
B12: Distance from factory (km) | C12: ='Price Calc'!B24 -> 50
B13: Prepared by | C13: ='Price Calc'!B15 -> Wolf Bierens
B15: BUILDING SPECIFICATION
B16: Easy Housing typology | C16: ='Price Calc'!B18 -> Large Gable (9768)
B17: Gross floor area (per home) | C17: ='Price Calc'!B19 -> 109.2
B18: Terrace | C18: ='Price Calc'!B20 -> 0
B19: Bedrooms | C19: ='Price Calc'!B21 -> 3
B20: Bathrooms | C20: ='Price Calc'!B22 -> 2
B21: Exterior doors & windows | C21: ='Project Input'!B37 -> 23.7
B22: Number of units | C22: ='Project Input'!B31 -> 1
B24: PRICE BREAKDOWN (all amounts include VAT)
B25: Item | C25: Size | D25: Unit | E25: ="Unit price ("&$H$5&")" -> Unit price (UGX) | F25: ="Amount ("&$H$5&")" -> Amount (UGX)
B26: Complete Easy Home (per unit) | F26: =IF($C$5="Kenya",'Price Calc'!K30,'Price Calc'!E30) -> 177216000
B27: Includes: all labour & overhead · full structure · paintworks · electrical installation · plumbing (where applicable). See price list for full inclusions.
B28: Additional options
B29: Burglar bars | C29: ='Price Calc'!B40 -> 0 | D29: ='Price Calc'!C40 -> sqm | E29: =IF($C$5="Kenya",'Price Calc'!J40,'Price Calc'!D40) -> 250000 | F29: =IF($C$5="Kenya",'Price Calc'!K40,'Price Calc'!E40) -> 0
B30: Terrace | C30: ='Price Calc'!B41 -> 0 | D30: ='Price Calc'!C41 -> sqm | E30: =IF($C$5="Kenya",'Price Calc'!J41,'Price Calc'!D41) -> 300000 | F30: =IF($C$5="Kenya",'Price Calc'!K41,'Price Calc'!E41) -> 0
B31: Pergola | C31: ='Price Calc'!B42 -> 0 | D31: ='Price Calc'!C42 -> sqm | E31: =IF($C$5="Kenya",'Price Calc'!J42,'Price Calc'!D42) -> 100000 | F31: =IF($C$5="Kenya",'Price Calc'!K42,'Price Calc'!E42) -> 0
B32: Railing (open) | C32: ='Price Calc'!B43 -> 0 | D32: ='Price Calc'!C43 -> m1 | E32: =IF($C$5="Kenya",'Price Calc'!J43,'Price Calc'!D43) -> 90000 | F32: =IF($C$5="Kenya",'Price Calc'!K43,'Price Calc'!E43) -> 0
B33: Railing (semi-closed) | C33: ='Price Calc'!B44 -> 0 | D33: ='Price Calc'!C44 -> m1 | E33: =IF($C$5="Kenya",'Price Calc'!J44,'Price Calc'!D44) -> 180000 | F33: =IF($C$5="Kenya",'Price Calc'!K44,'Price Calc'!E44) -> 0
B34: Wheelchair ramp | C34: ='Price Calc'!B45 -> 0 | D34: ='Price Calc'!C45 -> pcs | E34: =IF($C$5="Kenya",'Price Calc'!J45,'Price Calc'!D45) -> 1500000 | F34: =IF($C$5="Kenya",'Price Calc'!K45,'Price Calc'!E45) -> 0
B35: Tiles | D35: total | F35: =IF($C$5="Kenya",'Price Calc'!K46,'Price Calc'!E46) -> 0
B36: Sanitary wares | D36: total | F36: =IF($C$5="Kenya",'Price Calc'!K47,'Price Calc'!E47) -> 0
B37: Biodigester | D37: total | F37: =IF($C$5="Kenya",'Price Calc'!K48,'Price Calc'!E48) -> 0
B38: ='Price Calc'!A49 -> Other options: | F38: =IF($C$5="Kenya",'Price Calc'!K49,'Price Calc'!E49)
B39: Total additional options | F39: =IF($C$5="Kenya",'Price Calc'!K50,'Price Calc'!E50) -> 0
B40: Total price per home (incl. options) | F40: =IF($C$5="Kenya",'Price Calc'!K52,'Price Calc'!E52) -> 177216000
B41: Number of homes | C41: ='Price Calc'!B54 -> 1
B42: ="GRAND TOTAL · incl. VAT · "&$H$5 -> GRAND TOTAL · incl. VAT · UGX | E42: =IF($C$5="Kenya",'Price Calc'!K54,'Price Calc'!E54) -> 177216000
B45: WHAT'S INCLUDED
...

Sheet Project Budget
B2: EASY HOUSING — PROJECT BUDGET OVERVIEW
B3: Internal PM budget & procurement tracker · cost basis, ex VAT · use together with the Bill of Quantities tab
B5: Client / project | C5: ='Project Costs'!E24 -> One Bedroom Compact Gable | E5: Typology | F5: ='Project Costs'!E23 -> Large Gable (9768)
B6: Project code | C6: ='Project Costs'!B12 -> EH-000 | E6: GFA (per home) | F6: ='Project Costs'!B24 -> 109.17702
B7: Location | C7: ='Project Input'!B24 -> Sagala | E7: Number of units | F7: ='Project Input'!B31 -> 1
B9: All amounts below are per single home, in the project currency, excluding VAT. Enter actuals as the project progresses; variance updates automatically. Multiply by the number of units (above) for the project total.
B11: 1. MATERIALS & SUPPLIES
B12: Budget line | C12: ="Budget ("&'Project Costs'!$B$38&")" -> Budget (UGX) | D12: ="Actual ("&'Project Costs'!$B$38&")" -> Actual (UGX) | E12: Variance | F12: Source / note
B13: Timber (beams & planks) | C13: ='Project Costs'!M35 -> 14118331 | D13: 0 | E13: =C13-D13 -> 14118331 | F13: Project Costs M34
B14: Plywood | C14: ='Project Costs'!M34 -> 5860761.7 | D14: 0 | E14: =C14-D14 -> 5860761.7 | F14: Project Costs M33
B15: Roof sheets, screws, ridges, gutters | C15: ='Project Costs'!M28 -> 5912462 | D15: 0 | E15: =C15-D15 -> 5912462 | F15: Project Costs M27
B16: Roof insulation | C16: ='Project Costs'!M36 -> 714285 | D16: 0 | E16: =C16-D16 -> 714285 | F16: Project Costs M35
B17: Wall insulation | C17: ='Project Costs'!M37 -> 1200668 | D17: 0 | E17: =C17-D17 -> 1200668 | F17: Project Costs M36
B18: Foundation blocks | C18: ='Project Costs'!M25 -> 4005262.2 | D18: 0 | E18: =C18-D18 -> 4005262.2 | F18: Project Costs M24
B19: Cement boards (bathrooms) | C19: ='Project Costs'!M33 -> 2640698.3 | D19: 0 | E19: =C19-D19 -> 2640698.3 | F19: Project Costs M32
B20: Interior doors | C20: ='Project Costs'!M27 -> 3700000 | D20: 0 | E20: =C20-D20 -> 3700000 | F20: Project Costs M26
B21: Subtotal | C21: =SUM(C13:C20) -> 38152468 | D21: =SUM(D13:D20) -> 0 | E21: =SUM(E13:E20) -> 38152468
B23: 2. SUBCONTRACTORS (specialist trades)
B24: Budget line | C24: ="Budget ("&'Project Costs'!$B$38&")" -> Budget (UGX) | D24: ="Actual ("&'Project Costs'!$B$38&")" -> Actual (UGX) | E24: Variance | F24: Source / note
B25: Aluminium doors & windows (fabrication + install) | C25: =SUM('Project Costs'!J100:J116) -> 14030400 | D25: 0 | E25: =C25-D25 -> 14030400 | F25: Project Costs J99:J115 — incl. bulk-area input
B26: Paintworks (interior & exterior) | C26: ='Project Costs'!M29 -> 10974959 | D26: 0 | E26: =C26-D26 -> 10974959 | F26: Project Costs M28
B27: Electrical installation (MEP) | C27: ='Project Costs'!M31 -> 9188276.8 | D27: 0 | E27: =C27-D27 -> 9188276.8 | F27: Project Costs M30
B28: Plumbing (MEP) | C28: ='Project Costs'!M32 -> 3729425.6 | D28: 0 | E28: =C28-D28 -> 3729425.6 | F28: Project Costs M31
B29: Subtotal | C29: =SUM(C25:C28) -> 37923062 | D29: =SUM(D25:D28) -> 0 | E29: =SUM(E25:E28) -> 37923062
B31: 3. LOGISTICS & TRANSPORT
B32: Budget line | C32: ="Budget ("&'Project Costs'!$B$38&")" -> Budget (UGX) | D32: ="Actual ("&'Project Costs'!$B$38&")" -> Actual (UGX) | E32: Variance | F32: Source / note
B33: Transport of frames to site (within 100 km) | C33: ='Project Costs'!M30 -> 2019774.9 | D33: 0 | E33: =C33-D33 -> 2019774.9 | F33: Project Costs M29
B34: Subtotal | C34: =SUM(C33) -> 2019774.9 | D34: =SUM(D33) -> 0 | E34: =SUM(E33) -> 2019774.9
B36: PROCUREMENT BUDGET — per home | C36: =C21+C29+C34 -> 78095305 | D36: =D21+D29+D34 -> 0 | E36: =E21+E29+E34 -> 78095305
B37: Project total — procurement (× number of units) | C37: =C36*'Project Input'!B31 -> 78095305
B39: 4. LABOUR OVERVIEW (own crew — for scheduling)
B40: Labour activity | C40: Budget (days) | D40: Actual (days) | E40: Variance | F40: Source / note
B41: Prefabrication labour | C41: ='Project Costs'!R25 -> 70 | D41: 0 | E41: =C41-D41 -> 70
B42: Foundation casting & placement | C42: ='Project Costs'!R26 -> 11 | D42: 0 | E42: =C42-D42 -> 11
B43: Site placement labour | C43: ='Project Costs'!R27 -> 55 | D43: 0 | E43: =C43-D43 -> 55
B44: Site finishings | C44: ='Project Costs'!R28 -> 30 | D44: 0 | E44: =C44-D44 -> 30
B45: Paintworks (on site) | C45: ='Project Costs'!R29 -> 43 | D45: 0 | E45: =C45-D45 -> 43
B46: Project manager | C46: ='Project Costs'!R30 -> 13 | D46: 0 | E46: =C46-D46 -> 13
B47: Total labour | C47: =SUM(C41:C46) -> 222 | D47: =SUM(D41:D46) -> 0 | E47: =SUM(E41:E46) -> 222
B48: Day rate (carpenter, ex VAT) — assumption | C48: {=INDEX('Location Data'!N:N,MATCH('Project Costs'!B11,'Location Data'!A:A,0))} -> 15 | E48: Source: Location Data
...

Sheet Project Costs
A5: Easy Housing - Calculation Template 2026
A6: ! Do not share sheets or extracts externally unless authorised !
A8: Project parameters | I8: Calculations | J8: Typologies | L8: Floor frame A | M8: Floor frame B | N8: Floor frame C | O8: Floor frame D (3363) | P8: Foundation | Q8: Wall B low | R8: Wall C low | S8: Wall B high | T8: Wall C high | U8: Roof frame 1221 x 5685 (mono pitch) | V8: Roof frame 1598x 5685 (mono pitch edge) | W8: Roof frame 1221 x 3574 (compact gable) | X8: Roof frame 1689 x 3574 (compact gable edge) | Y8: Roof frame 1221 x 4194 (standard gable) | Z8: Roof frame 1689 x 4194 (standard gable edge) | AA8: Roof frame 1221 x 5435 (large gable) | AB8: Roof frame 1689 x 5435 (large gable edge) | AC8: Roof frame 1221 x 5780 (clerestory upper) | AD8: Roof frame 1689 x 5780 (clerestory upper edge) | AE8: Roof frame 1221 x 4194 (clerestory lower) | AF8: Roof frame 1689 x 4194 (clerestory lower edge)
J9: ='Price Calc'!A88 -> Mono Pitch (4884) | L9: =2*$E$25 -> 0 | M9: =2*$E$26 -> 4 | N9: =2*$E$27 -> 4 | O9: =2*$E$27 -> 4 | P9: =3*(SUM($E$25:$E$27)+1) -> 15 | Q9: =E26+0.5*E25 -> 2 | R9: =E27 -> 2 | S9: =4+E26+0.5*E25 -> 6 | T9: =E27 -> 2 | U9: =E25+2*E26+2.5*E27-2 -> 7 | V9: 2
J10: ='Price Calc'!A89 -> Small Gable (4884) | L10: =L9 -> 0 | M10: =M9 -> 4 | N10: =N9 -> 4 | O10: =O9 -> 4 | P10: =P9 -> 15 | Q10: =Q9 -> 2 | R10: =R9 -> 2 | S10: =S9 -> 6 | T10: =T9 -> 2 | Y10: =Y12 -> 14 | Z10: =Z12 -> 4
A11: Project location parameters | B11: Kampala, Uganda | J11: ='Price Calc'!A90 -> Compact Gable (6106) | L11: 0 | M11: 0 | N11: =E26*2+E25 -> 4 | O11: =2*$E$27 -> 4 | P11: =3*(SUM($E$25:$E$27)+1) -> 15 | Q11: =E26*2+E25 -> 4 | R11: 0 | S11: 0 | T11: 4 | W11: =(E25+2*E26+2.5*E27-2)*2 -> 14 | X11: 4
A12: Project code | B12: EH-000 | J12: ='Price Calc'!A91 -> Standard Gable (7326) | L12: =3*$E$25 -> 0 | M12: =3*$E$26 -> 6 | N12: =3*$E$27 -> 6 | O12: =2*$E$27 -> 4 | P12: =4*(SUM($E$25:$E$27)+1) -> 20 | Q12: =E26*2+E25 -> 4 | R12: =E27*2 -> 4 | S12: 6 | T12: 0 | Y12: =(E25+2*E26+2.5*E27-2)*2 -> 14 | Z12: 4
A13: Project name | J13: ='Price Calc'!A92 -> Large Gable (9768) | L13: =4*$E$25 -> 0 | M13: =4*$E$26 -> 8 | N13: =4*$E$27 -> 8 | O13: =2*$E$27 -> 4 | P13: =5*(SUM($E$25:$E$27)+1) -> 25 | Q13: =E26*2+E25 -> 4 | R13: =E27*2 -> 4 | S13: 8 | T13: 0 | AA13: =Y12 -> 14 | AB13: =Z12 -> 4
A14: Project Location | B14: Greater Kampala (<100km from factory) | J14: ='Price Calc'!A93 -> Standard Clerestory (7326) | L14: =3*$E$25 -> 0 | M14: =3*$E$26 -> 6 | N14: =3*$E$27 -> 6 | O14: =2*$E$27 -> 4 | P14: =4*(SUM($E$25:$E$27)+1) -> 20 | Q14: =E26+0.5*E25 -> 2 | R14: =E27 -> 2 | S14: =6+E26+0.5*E25 -> 8 | T14: =E27 -> 2 | AC14: =U9 -> 7 | AD14: 2 | AE14: =AC14 -> 7 | AF14: 2
A15: Client name | B15: Example calculation | J15: ='Price Calc'!A94 -> Large Clerestory (8547) | L15: =3.5*$E$25 -> 0 | M15: =3.5*$E$26 -> 7 | N15: =3.5*$E$27 -> 7 | O15: =2*$E$27 -> 4 | P15: =5*(SUM($E$25:$E$27)+1) -> 25 | Q15: =Q14 -> 2 | R15: =R14 -> 2 | S15: =S14+1 -> 9 | T15: =T14 -> 2 | AC15: =AC14 -> 7 | AD15: 2 | AE15: =AC14 -> 7 | AF15: 2
J16: ='Price Calc'!A95 -> A Frame Compact (3663) | O16: =E26+0.5*E25 -> 2 | P16: =2*(SUM($E$25:$E$27)+1) -> 10 | T16: 2 | U16: =2*(E25+2*E26+2.5*E27-2) -> 14 | V16: 4
J17: ='Price Calc'!A96 -> A Frame Standard (4884) | M17: =2*E26+E25 -> 4 | O17: =2*$E$27 -> 4 | P17: =3*(SUM($E$25:$E$27)+1) -> 15 | S17: 4 | U17: =2*(E25+2*E26+2.5*E27-2) -> 14 | V17: 4
J18: ='Price Calc'!A97 -> A Frame Large (6106) | N18: =2*E26 -> 4 | O18: =2*$E$27 -> 4 | P18: =3*(SUM($E$25:$E$27)+1) -> 15 | T18: 4 | U18: =2*(E25+2*E26+2.5*E27-2) -> 14 | V18: 4
A19: Date created | B19: =TODAY() -> 46195 | I19: Selected: | J19: =E23 -> Large Gable (9768) | L19: =INDEX(L9:L18,MATCH($J$19,$J$9:$J$18,0),1) -> 0 | M19: =INDEX(M9:M18,MATCH($J$19,$J$9:$J$18,0),1) -> 8 | N19: =INDEX(N9:N18,MATCH($J$19,$J$9:$J$18,0),1) -> 8 | O19: =INDEX(O9:O18,MATCH($J$19,$J$9:$J$18,0),1) -> 4 | P19: =INDEX(P9:P18,MATCH($J$19,$J$9:$J$18,0),1) -> 25 | Q19: =INDEX(Q9:Q18,MATCH($J$19,$J$9:$J$18,0),1) -> 4 | R19: =INDEX(R9:R18,MATCH($J$19,$J$9:$J$18,0),1) -> 4 | S19: =INDEX(S9:S18,MATCH($J$19,$J$9:$J$18,0),1) -> 8 | ... AF19: =INDEX(AF9:AF18,MATCH($J$19,$J$9:$J$18,0),1)
A22: Building parameters | D22: Quick Input Tool - now linked to input tab, do not overwrite | J22: Subcontractor / supplier budget overview * | O22: Labour time overview
A23: Building typology | B23: =E23 -> Large Gable (9768) | D23: Typology | E23: ='Project Input'!B30 -> Large Gable (9768)
A24: Gross floor surface (sqm) | B24: =SUM(V69:V71)+0.044*(A76*2.442+A77*3.053+A78*2.442+A79*3.053) -> 109.17702 | D24: Name | E24: ='Project Input'!B22 -> One Bedroom Compact Gable | J24: Description | M24: =B38&" ex VAT **" -> UGX ex VAT ** | O24: Description | R24: Labour days
A25: Decking surface area (sqm) | B25: =SUM(V73:V75) -> 0 | D25: Floor A - 1221 | E25: ='Project Input'!B32 -> 0 | F25: columns | J25: Foundation blocks | M25: =J122 -> 4005262.2 | O25: Prefabrication labour | R25: =ROUNDUP(SUM(T69:T95)/8,0) -> 70
A26: Net floor surface without decking/walls | B26: =SUM(V69:V71)-0.099*(A76*2.442+A77*3.053+A78*2.442+A79*3.053) -> 103.24024 | D26: Floor B - 2442 | E26: ='Project Input'!B33 -> 2 | F26: columns | G26: use for compact gable | J26: Aluminium doors and windows | M26: =SUM(J100:J115) -> 0 | O26: Foundation casting and placement | R26: =ROUND(T122/8,0) -> 11
A27: Exterior wall surface (sqm) | B27: =SUM(V76:V79) -> 124.06414 | D27: Floor C - 3053 | E27: ='Project Input'!B34 -> 2 | F27: columns | J27: Interior doors | M27: =J123 -> 3700000 | O27: Site placement labour | R27: =ROUNDUP(0.5*$B$24,0) -> 55
A28: Outer windows and doors (sqm) | B28: =SUM(V100:V115)+A116 -> 23.7 | D28: Partitions | E28: ='Project Input'!B35 -> 33 | F28: m1 / default at 30% of GFA | G28: 0.3 | H28: =G23*B19 | J28: Roof sheets, inc screws, ridges, gutters, labour | M28: =J124 -> 5912462 | O28: Site finishings (steps, fascia, skirts, substrate) | R28: =ROUNDUP(B24*0.2+2+A126*0.2+A127,0) -> 30
A29: Net facade surface (sqm) | B29: =B27-B28 -> 100.36414 | D29: Interior doors | E29: ='Project Input'!B36 -> 5 | F29: pcs | J29: Paint works interior and exterior | M29: =J125 -> 10974959 | O29: Paint works (on site) | R29: =ROUND(T125/8,0) -> 43
A30: Partition wall surface (sqm) | B30: =V80*2 -> 198 | D30: Aluminium | E30: ='Project Input'!B37 -> 23.7 | F30: sqm / default at 20% of ext wall surface | G30: 0.2 | H30: =G25*B22 | J30: Truck frames transport to sites <100 km | M30: =J138 -> 2019774.9 | O30: Project manager | R30: =ROUND(2+0.1*B24,0) -> 13
A31: Roof surface (sqm) | B31: =SUM(V83:V94) -> 130.62967 | D31: Extra ext. wall | E31: 0 | F31: grid steps 61cm (indents etc) | J31: Electricity | M31: =J156 -> 9188276.8 | O31: Total | R31: =SUM(R25:R30) -> 222 | S31: days
A32: Number ext doors and windows (if filled) | B32: =SUM(A100:A115) -> 0 | D32: Veranda A | E32: 0 | F32: frames | J32: Plumbing | M32: =J157 -> 3729425.6 | R32: =R31*8 -> 1776 | S32: hours
A33: Foundation type | B33: ='Bill of Quantities'!C35 -> Foundation block | D33: Veranda B | E33: 0 | F33: frames | J33: Cement boards bathrooms | M33: =J127 -> 2640698.3
A34: Foundation average height (mm) | B34: 400 | D34: Veranda C | E34: =ROUNDUP('Project Input'!B44/(3.05*2.44),0) -> 0 | F34: frames | J34: Plywood | M34: =SUM('Bill of Quantities'!P52:P55)*B39 -> 5860761.7
A35: Distance from workshop (km) | B35: ='Project Input'!B25 -> 50 | D35: Bathrooms | E35: ='Project Input'!B39 -> 2 | F35: bathroom(s) | J35: Timber | M35: ='Timber Order'!H35*'Bill of Quantities'!D14*B39 -> 14118331
J36: Roof insulation | M36: ='Bill of Quantities'!P83*B39 -> 714285
A37: Price information (outdated) | J37: Wall insulation | M37: ='Bill of Quantities'!P84*B39 -> 1200668
A38: ='Location Data'!C5 -> Currency | B38: {=INDEX('Location Data'!C:C,MATCH($B$11,'Location Data'!A:A,0),1)} -> UGX | J38: Total | M38: =SUM(M24:M37) -> 64064905
A39: ='Location Data'!D5 -> Conversion rate from USD | B39: {=INDEX('Location Data'!D:D,MATCH($B$11,'Location Data'!A:A,0),1)} -> 3700
A40: Margin | B40: 0.1
A41: ='Location Data'!E5 -> Value added tax (VAT) | B41: {=INDEX('Location Data'!E:E,MATCH($B$11,'Location Data'!A:A,0),1)} -> 0.18 | J41: * subcontractor budgets are exclusive of VAT
A42: Cost price in USD ex VAT | B42: =D64 -> 33272.618 | J42: ** budgets incl all material, labour,transportation costs
A43: Margin | B43: =B42*B40 -> 3327.2618 | D43: Standard models
A44: Licence Fee Easy Building | B44: =C135 -> 4367.081
A45: Sales price in USD ex VAT | B45: =B42+B43 -> 36599.88 | D45: Typology | E45: =J9 -> Mono Pitch (4884) | F45: =E45 -> Mono Pitch (4884) | G45: =F45 -> Mono Pitch (4884) | H45: =G45 -> Mono Pitch (4884) | I45: Compact Gable 6106 | J45: Compact Gable 6106 | K45: Compact Gable 6106 | L45: Compact Gable 6106 | M45: Compact Gable 6106 | N45: Standard Gable 7326 | O45: Standard Gable 7326 | P45: Standard Gable 7326 | Q45: Large Gable 9768 | R45: Clerestory 8547 | S45: Clerestory 8547 | T45: Clerestory 8547 | U45: Compact Gable 6106 | V45: Clerestory 7326 | W45: Clerestory 8547 | X45: Compact Gable 6106 | Y45: Mono Pitch 4884 | Z45: Clerestory 8547 | AA45: Mono Pitch 4884 | AB45: Clerestory 8547 | AC45: A Frame Large | AD45: A Frame Compact | AE45: A Frame Standard
A46: Price in USD in VAT | B46: =B45*B41+B45 -> 43187.858 | D46: Building width | E46: Studio | F46: 1BR Mono | G46: 2BR Mono | H46: 3BR Mono | I46: 1BR Compact Gable | J46: 2BR Compact Gable | K46: 3BR Compact Gable | L46: 4BR Compact Gable | M46: 2BR Comfort Compact Gable | N46: 2BR Gable | O46: 3BR Gable | P46: 4BR Gable | Q46: 3BR Large Gable | R46: 2BR Clerestory | S46: 4BR Clerestory | T46: Nisha's | U46: John's | V46: Sarah's | W46: Naomi & Jesse | X46: Mlango Farm | Y46: Milly | Z46: Naomi & Jesse | AA46: Janet | AB46: Pius O | AC46: Zziwa test | AD46: Compact A Frame | AE46: Standard A Frame
A47: Price per sqm GFA in USD in VAT | B47: =B46/B24 -> 395.57644 | D47: Floor A - 1221 | E47: 0 | F47: 0 | G47: 0 | H47: 0 | I47: 0 | J47: 0 | K47: 1 | L47: 0 | M47: 0 | N47: 0 | O47: 0 | P47: 0 | Q47: 0 | R47: 1 | S47: 1 | T47: 2 | U47: 0 | V47: 0 | W47: 2 | X47: 0 | Y47: 0 | Z47: 2 | AA47: 0 | AB47: 2 | AC47: 0 | AD47: 0 | AE47: 0
...

Sheet Price Calc
A1: EASY HOUSING — PRICE CALCULATION
A2: Internal sales-price engine — Uganda (UGX) & Kenya (KES). Inputs flow in from the Project Input tab. Edit only the highlighted rate cells.
A3: UGANDA · UGX | G3: KENYA · KES
A4: General Information | G4: General Information
A5: Quotation Date | B5: =TODAY() -> 46195 | G5: Quotation Date | H5: =TODAY() -> 46195
A6: Validity | B6: One month | G6: Validity | H6: One month
A8: All prices are inclusive of VAT | G8: All prices are inclusive of VAT
A9: All prices are in Ugandan Shillings (UGX) | G9: All prices are in Kenyan Shillings (KES)
A10: No rights can be derived from this quote | G10: No rights can be derived from this quote
A12: Client Information | G12: Client Information
A13: Client Name | B13: ='Project Input'!B22 -> One Bedroom Compact Gable | G13: Client Name | H13: =B13 -> One Bedroom Compact Gable
A14: Contact Details | B14: ='Project Input'!B23 -> +256 712 345 678 | G14: Contact Details | H14: =B14 -> +256 712 345 678
A15: Created by | B15: ='Project Input'!B27 -> Wolf Bierens | G15: Quotation Made By | H15: =B15 -> Wolf Bierens
A17: Project information | G17: Project information
A18: Easy Housing Typology | B18: =B59 -> Large Gable (9768) | G18: Easy Housing Typology | H18: =B18 -> Large Gable (9768)
A19: Gross Floor Area (sqm) | B19: =B63 -> 109.2 | G19: Gross Floor Area (sqm) | H19: =B19 -> 109.2
A20: Terrace (sqm) | B20: =B41 -> 0 | G20: Terrace (sqm) | H20: =B20 -> 0
A21: Bedrooms | B21: =B70 -> 3 | G21: Bedrooms | H21: =B21 -> 3
A22: Bathrooms | B22: =B71 -> 2 | G22: Bathrooms | H22: =B22 -> 2
A23: Project Location | B23: ='Project Input'!B24 -> Sagala | G23: Project Location | H23: =B23 -> Sagala
A24: Distance from factory | B24: ='Project Input'!B25 -> 50 | G24: Distance from factory | H24: =B24 -> 50
A26: Quotation Price Breakdown | G26: Quotation Price Breakdown
A28: Price Breakdown | E28: Price (UGX) | G28: Price Breakdown | K28: Price (KES)
A30: Complete Easy Home | E30: =E82 -> 177216000 | G30: Complete Easy Home | K30: =G82 -> 6793780
A31: Includes: | G31: Includes:
A32: All labour and overhead | G32: All labour and overhead
A33: Full structure | G33: Full structure
A34: Paintworks | G34: Paintworks
A35: Electrical installations | G35: Electrical installations
A36: Plumbing (if any) | G36: Plumbing (if any)
A37: See price list for more details | G37: See price list for more details
A39: Additional options | B39: Size | C39: Unit | D39: Unit price | E39: Price (UGX) | G39: Additional options | H39: Size | I39: Unit | J39: Unit price | K39: Price (KES)
A40: Burglar bars | B40: ='Project Input'!B49 -> 0 | C40: sqm | D40: 250000 | E40: =B40*D40 -> 0 | F40: For standard design burglar bars of steel | G40: Burglar bars | H40: =B40 -> 0 | I40: =C40 -> sqm | J40: 7500 | K40: =H40*J40 -> 0
A41: Terrace | B41: ='Project Input'!B44 -> 0 | C41: sqm | D41: 300000 | E41: =B41*D41 -> 0 | F41: In standard size frames, including linseed oil finishing and foundation work | G41: Terrace | H41: =B41 -> 0 | I41: =C41 -> sqm | J41: 12000 | K41: =H41*J41 -> 0
A42: Pergola | B42: ='Project Input'!B45 -> 0 | C42: sqm | D42: 100000 | E42: =B42*D42 -> 0 | F42: For an open structure pergola with beams every 60 cm | G42: Pergola | H42: =B42 -> 0 | I42: =C42 -> sqm | J42: 4000 | K42: =H42*J42 -> 0
A43: Railing open | B43: ='Project Input'!B46 -> 0 | C43: m1 | D43: 90000 | E43: =B43*D43 -> 0 | F43: With studs every 1.2m | G43: Railing open | H43: =B43 -> 0 | I43: =C43 -> m1 | J43: 3500 | K43: =H43*J43 -> 0
A44: Railing semi-closed | B44: ='Project Input'!B47 -> 0 | C44: m1 | D44: 180000 | E44: =B44*D44 -> 0 | F44: With studs every 20 cm so that kids and animals cannot fall through | G44: Railing semi-closed | H44: =B44 -> 0 | I44: =C44 -> m1 | J44: 7000 | K44: =H44*J44 -> 0
A45: Wheelchair ramp | B45: ='Project Input'!B50 -> 0 | C45: pcs | D45: 1500000 | E45: =B45*D45 -> 0 | F45: For an average ramp of around 5m long (low inclination) | G45: Wheelchair ramp | H45: =B45 -> 0 | I45: =C45 -> pcs | J45: 6500 | K45: =H45*J45 -> 0
A46: Tiles | C46: total | E46: ='Project Input'!B51 -> 0 | G46: Tiles | I46: =C46 -> total | K46: ='Project Input'!B51 -> 0
A47: Sanitary wares | C47: total | E47: ='Project Input'!B52 -> 0 | G47: Sanitary wares | I47: =C47 -> total | K47: ='Project Input'!B52 -> 0
...

Sheet Catalogue Prices 2026
A1: Prices including VAT per Q1 2025
A3: Uganda | B3: GFA | C3: Basic home | E3: Tier 1 finishings | H3: Total inc tier 1 finishings | K3: Price ex finishing per GFA | L3: Price inc finishing per GFA | M3: Licence fee | O3: Bathrooms | P3: Kitchen blocks
A4: Model | C4: USD | D4: UGX | E4: USD | G4: UGX | H4: USD | I4: UGX
A5: Studio | B5: 25 | C5: =D5/3700 -> 9121.6216 | D5: =B5*1350000 -> 33750000 | E5: =G5/3700 -> 1689.1892 | G5: =B5*250000 -> 6250000 | H5: =I5/3700 -> 10810.811 | I5: =D5+G5 -> 40000000 | K5: =C5/B5 -> 364.86486 | L5: =H5/B5 -> 432.43243 | M5: =B5*25 -> 625 | N5: =K5*3700 -> 1350000 | O5: 1 | P5: 5
A6: One Bedroom Mono | B6: 37 | C6: =D6/3700 -> 13500 | D6: =B6*1350000 -> 49950000 | E6: =G6/3700 -> 2500 | G6: =B6*250000 -> 9250000 | H6: =I6/3700 -> 16000 | I6: =D6+G6 -> 59200000 | K6: =C6/B6 -> 364.86486 | L6: =H6/B6 -> 432.43243 | M6: =B6*25 -> 925 | N6: =K6*3700 -> 1350000 | O6: 1 | P6: 4
A7: Two Bedroom Mono | B7: 43 | C7: =D7/3700 -> 15689.189 | D7: =B7*1350000 -> 58050000 | E7: =G7/3700 -> 2905.4054 | G7: =B7*250000 -> 10750000 | H7: =I7/3700 -> 18594.595 | I7: =D7+G7 -> 68800000 | K7: =C7/B7 -> 364.86486 | L7: =H7/B7 -> 432.43243 | M7: =B7*25 -> 1075 | N7: =K7*3700 -> 1350000 | O7: 1 | P7: 5
A8: Three Bedroom Mono | B8: 46 | C8: =D8/3700 -> 16783.784 | D8: =B8*1350000 -> 62100000 | E8: =G8/3700 -> 3108.1081 | G8: =B8*250000 -> 11500000 | H8: =I8/3700 -> 19891.892 | I8: =D8+G8 -> 73600000 | K8: =C8/B8 -> 364.86486 | L8: =H8/B8 -> 432.43243 | M8: =B8*25 -> 1150 | N8: =K8*3700 -> 1350000 | O8: 1 | P8: 4
A9: One Bedroom Compact Gable | B9: 46 | O9: 1 | P9: 6
A10: Two Bedroom Compact Gable | B10: 61 | O10: 2 | P10: 6
A11: Three Bedroom Compact Gable | B11: 69 | O11: 2 | P11: 6
A12: Four Bedroom Compact Gable | B12: 76 | O12: 2 | P12: 6
A13: Two Bedroom Comfort Compact Gable | B13: 76 | O13: 2 | P13: 6
A14: Two Bedroom Gable | B14: 87 | C14: =D14/3700 -> 31743.243 | D14: =B14*1350000 -> 117450000 | E14: =G14/3700 -> 5878.3784 | G14: =B14*250000 -> 21750000 | H14: =I14/3700 -> 37621.622 | I14: =D14+G14 -> 139200000 | K14: =C14/B14 -> 364.86486 | L14: =H14/B14 -> 432.43243 | M14: =B14*25 -> 2175 | N14: =K14*3700 -> 1350000 | O14: 2 | P14: 7
A15: Three Bedroom Gable | B15: 96 | C15: =D15/3700 -> 35027.027 | D15: =B15*1350000 -> 129600000 | E15: =G15/3700 -> 6486.4865 | G15: =B15*250000 -> 24000000 | H15: =I15/3700 -> 41513.514 | I15: =D15+G15 -> 153600000 | K15: =C15/B15 -> 364.86486 | L15: =H15/B15 -> 432.43243 | M15: =B15*25 -> 2400 | N15: =K15*3700 -> 1350000 | O15: 3 | P15: 7
A16: Four Bedroom Gable | B16: 105 | C16: =D16/3700 -> 38310.811 | D16: =B16*1350000 -> 141750000 | E16: =G16/3700 -> 7094.5946 | G16: =B16*250000 -> 26250000 | H16: =I16/3700 -> 45405.405 | I16: =D16+G16 -> 168000000 | K16: =C16/B16 -> 364.86486 | L16: =H16/B16 -> 432.43243 | M16: =B16*25 -> 2625 | N16: =K16*3700 -> 1350000 | O16: 3 | P16: 7
A17: Three Bedroom Large Gable | B17: 109 | C17: =D17/3700 -> 39770.27 | D17: =B17*1350000 -> 147150000 | E17: =G17/3700 -> 7364.8649 | G17: =B17*250000 -> 27250000 | H17: =I17/3700 -> 47135.135 | I17: =D17+G17 -> 174400000 | K17: =C17/B17 -> 364.86486 | L17: =H17/B17 -> 432.43243 | M17: =B17*25 -> 2725 | N17: =K17*3700 -> 1350000 | O17: 2 | P17: 8
A18: Two Bedroom Clerestory | B18: 64 | C18: =D18/3700 -> 24562.162 | D18: =B18*1420000 -> 90880000 | E18: =G18/3700 -> 4324.3243 | G18: =B18*250000 -> 16000000 | H18: =I18/3700 -> 28886.486 | I18: =D18+G18 -> 106880000 | K18: =C18/B18 -> 383.78378 | L18: =H18/B18 -> 451.35135 | M18: =B18*25 -> 1600 | N18: =K18*3700 -> 1420000 | O18: 1 | P18: 7
A19: Four Bedroom Clerestory | B19: 106 | C19: =D19/3700 -> 40681.081 | D19: =B19*1420000 -> 150520000 | E19: =G19/3700 -> 7162.1622 | G19: =B19*250000 -> 26500000 | H19: =I19/3700 -> 47843.243 | I19: =D19+G19 -> 177020000 | K19: =C19/B19 -> 383.78378 | L19: =H19/B19 -> 451.35135 | M19: =B19*25 -> 2650 | N19: =K19*3700 -> 1420000 | O19: 2 | P19: 7
A22: All models except clerestory at 1.35M per sqm. Clerestory at 1.42M per sqm.
A23: Uganda | C23: UGX | M23: Transposed for brochure
A24: Model | B24: Floor area | C24: Basic structure | D24: Electricals | E24: Plumbing | F24: Total | G24: Tiling | H24: Sanitary wares | I24: Kitchen block | J24: Grand total | K24: Basic in USD | L24: Full in USD | N24: Studio | O24: One Bedroom Mono | P24: Two Bedroom Mono | Q24: Three Bedroom Mono | R24: Two Bedroom Gable | S24: Three Bedroom Gable | T24: Four Bedroom Gable | U24: Three Bedroom Large Gable | V24: Two Bedroom Clerestory | W24: Four Bedroom Clerestory
A25: Studio | B25: =B5 -> 25 | C25: =B25*1350000 -> 33750000 | D25: =1500000+50000*B25 -> 2750000 | E25: =500000+O5*1000000+B5*20000 -> 2000000 | F25: =C25+D25+E25 -> 38500000 | G25: =80000*12*O5 -> 960000 | H25: =2300000*O5 -> 2300000 | I25: =2000000+500000*P5 -> 4500000 | J25: =SUM(C25:I25) -> 84760000 | K25: =C25/'Location Data'!$D$6 -> 9121.6216 | L25: =J25/'Location Data'!$D$6 -> 22908.108 | M25: Basic structure | N25: 33750000 | O25: 41850000 | P25: 58050000 | Q25: 62100000 | R25: 117450000 | S25: 129600000 | T25: 141750000 | U25: 147150000 | V25: 86400000 | W25: 122850000
A26: One Bedroom Mono | B26: 37 | C26: =B26*1350000 -> 49950000 | D26: =1500000+50000*B26 -> 3350000 | E26: =500000+O6*1000000+B6*20000 -> 2240000 | F26: =C26+D26+E26 -> 55540000 | G26: =80000*12*O6 -> 960000 | H26: =2300000*O6 -> 2300000 | I26: =I25 -> 4500000 | J26: =SUM(C26:I26) -> 118840000 | K26: =C26/'Location Data'!$D$6 -> 13500 | L26: =J26/'Location Data'!$D$6 -> 32118.919 | M26: Electricals | N26: 2750000 | O26: 3050000 | P26: 3650000 | Q26: 3800000 | R26: 5850000 | S26: 6300000 | T26: 6750000 | U26: 6950000 | V26: 4700000 | W26: 6050000
A27: Two Bedroom Mono | B27: =B7 -> 43 | C27: =B27*1350000 -> 58050000 | D27: =1500000+50000*B27 -> 3650000 | E27: =500000+O7*1000000+B7*20000 -> 2360000 | F27: =C27+D27+E27 -> 64060000 | G27: =80000*12*O7 -> 960000 | H27: =2300000*O7 -> 2300000 | I27: =2000000+500000*P7 -> 4500000 | J27: =SUM(C27:I27) -> 135880000 | K27: =C27/'Location Data'!$D$6 -> 15689.189 | L27: =J27/'Location Data'!$D$6 -> 36724.324 | M27: Plumbing | N27: 2000000 | O27: 2120000 | P27: 2360000 | Q27: 2420000 | R27: 4240000 | S27: 5420000 | T27: 5600000 | U27: 4680000 | V27: 2780000 | W27: 4320000
A28: Three Bedroom Mono | B28: =B8 -> 46 | C28: =B28*1350000 -> 62100000 | D28: =1500000+50000*B28 -> 3800000 | E28: =500000+O8*1000000+B8*20000 -> 2420000 | F28: =C28+D28+E28 -> 68320000 | G28: =80000*12*O8 -> 960000 | H28: =2300000*O8 -> 2300000 | I28: =2000000+500000*P8 -> 4000000 | J28: =SUM(C28:I28) -> 143900000 | K28: =C28/'Location Data'!$D$6 -> 16783.784 | L28: =J28/'Location Data'!$D$6 -> 38891.892 | M28: Tiling | N28: 960000 | O28: 960000 | P28: 960000 | Q28: 960000 | R28: 1920000 | S28: 2880000 | T28: 2880000 | U28: 1920000 | V28: 960000 | W28: 1920000
A29: One Bedroom Compact Gable | B29: 46 | C29: =B29*1350000 -> 62100000 | D29: =1500000+50000*B29 -> 3800000 | E29: =500000+O9*1000000+B9*20000 -> 2420000 | F29: =C29+D29+E29 -> 68320000 | G29: =80000*12*O9 -> 960000 | H29: =2300000*O9 -> 2300000 | I29: =2000000+500000*P9 -> 5000000 | J29: =SUM(C29:I29) -> 144900000 | K29: =C29/'Location Data'!$D$6 -> 16783.784 | L29: =J29/'Location Data'!$D$6 -> 39162.162 | M29: Sanitary wares | N29: 2300000 | O29: 2300000 | P29: 2300000 | Q29: 2300000 | R29: 4600000 | S29: 6900000 | T29: 6900000 | U29: 4600000 | V29: 2300000 | W29: 4600000
A30: Two Bedroom Compact Gable | B30: 61 | C30: =B30*1350000 -> 82350000 | D30: =1500000+50000*B30 -> 4550000 | E30: =500000+O10*1000000+B10*20000 -> 3720000 | F30: =C30+D30+E30 -> 90620000 | G30: =80000*12*O10 -> 1920000 | H30: =2300000*O10 -> 4600000 | I30: =2000000+500000*P10 -> 5000000 | J30: =SUM(C30:I30) -> 192760000 | K30: =C30/'Location Data'!$D$6 -> 22256.757 | L30: =J30/'Location Data'!$D$6 -> 52097.297 | M30: Kitchen block | N30: 4500000 | O30: 4500000 | P30: 4500000 | Q30: 4000000 | R30: 5500000 | S30: 5500000 | T30: 5500000 | U30: 6000000 | V30: 5500000 | W30: 5500000
A31: Three Bedroom Compact Gable | B31: 69 | C31: =B31*1350000 -> 93150000 | D31: =1500000+50000*B31 -> 4950000 | E31: =500000+O11*1000000+B11*20000 -> 3880000 | F31: =C31+D31+E31 -> 101980000 | G31: =80000*12*O11 -> 1920000 | H31: =2300000*O11 -> 4600000 | I31: =2000000+500000*P11 -> 5000000 | J31: =SUM(C31:I31) -> 215480000 | K31: =C31/'Location Data'!$D$6 -> 25175.676 | L31: =J31/'Location Data'!$D$6 -> 58237.838 | M31: Grand total | N31: 46260000 | O31: 54780000 | P31: 71820000 | Q31: 75580000 | R31: 139560000 | S31: 156600000 | T31: 169380000 | U31: 171300000 | V31: 102640000 | W31: 145240000
A32: Four Bedroom Compact Gable | B32: 76 | C32: =B32*1350000 -> 102600000 | D32: =1500000+50000*B32 -> 5300000 | E32: =500000+O12*1000000+B12*20000 -> 4020000 | F32: =C32+D32+E32 -> 111920000 | G32: =80000*12*O12 -> 1920000 | H32: =2300000*O12 -> 4600000 | I32: =2000000+500000*P12 -> 5000000 | J32: =SUM(C32:I32) -> 235360000 | K32: =C32/'Location Data'!$D$6 -> 27729.73 | L32: =J32/'Location Data'!$D$6 -> 63610.811
A33: Two Bedroom Comfort Compact Gable | B33: 76 | C33: =B33*1350000 -> 102600000 | D33: =1500000+50000*B33 -> 5300000 | E33: =500000+O13*1000000+B13*20000 -> 4020000 | F33: =C33+D33+E33 -> 111920000 | G33: =80000*12*O13 -> 1920000 | H33: =2300000*O13 -> 4600000 | I33: =2000000+500000*P13 -> 5000000 | J33: =SUM(C33:I33) -> 235360000 | K33: =C33/'Location Data'!$D$6 -> 27729.73 | L33: =J33/'Location Data'!$D$6 -> 63610.811
A34: Two Bedroom Gable | B34: =B14 -> 87 | C34: =B34*1350000 -> 117450000 | D34: =1500000+50000*B34 -> 5850000 | E34: =500000+O14*1000000+B14*20000 -> 4240000 | F34: =C34+D34+E34 -> 127540000 | G34: =80000*12*O14 -> 1920000 | H34: =2300000*O14 -> 4600000 | I34: =2000000+500000*P14 -> 5500000 | J34: =SUM(C34:I34) -> 267100000 | K34: =C34/'Location Data'!$D$6 -> 31743.243 | L34: =J34/'Location Data'!$D$6 -> 72189.189
A35: Three Bedroom Gable | B35: =B15 -> 96 | C35: =B35*1350000 -> 129600000 | D35: =1500000+50000*B35 -> 6300000 | E35: =500000+O15*1000000+B15*20000 -> 5420000 | F35: =C35+D35+E35 -> 141320000 | G35: =80000*12*O15 -> 2880000 | H35: =2300000*O15 -> 6900000 | I35: =2000000+500000*P15 -> 5500000 | J35: =SUM(C35:I35) -> 297920000 | K35: =C35/'Location Data'!$D$6 -> 35027.027 | L35: =J35/'Location Data'!$D$6 -> 80518.919
A36: Four Bedroom Gable | B36: =B16 -> 105 | C36: =B36*1350000 -> 141750000 | D36: =1500000+50000*B36 -> 6750000 | E36: =500000+O16*1000000+B16*20000 -> 5600000 | F36: =C36+D36+E36 -> 154100000 | G36: =80000*12*O16 -> 2880000 | H36: =2300000*O16 -> 6900000 | I36: =2000000+500000*P16 -> 5500000 | J36: =SUM(C36:I36) -> 323480000 | K36: =C36/'Location Data'!$D$6 -> 38310.811 | L36: =J36/'Location Data'!$D$6 -> 87427.027
A37: Three Bedroom Large Gable | B37: =B17 -> 109 | C37: =B37*1350000 -> 147150000 | D37: =1500000+50000*B37 -> 6950000 | E37: =500000+O17*1000000+B17*20000 -> 4680000 | F37: =C37+D37+E37 -> 158780000 | G37: =80000*12*O17 -> 1920000 | H37: =2300000*O17 -> 4600000 | I37: =2000000+500000*P17 -> 6000000 | J37: =SUM(C37:I37) -> 330080000 | K37: =C37/'Location Data'!$D$6 -> 39770.27 | L37: =J37/'Location Data'!$D$6 -> 89210.811
A38: Two Bedroom Large Clerestory | B38: =B18 -> 64 | C38: =D18 -> 90880000 | D38: =1500000+50000*B38 -> 4700000 | E38: =500000+O18*1000000+B18*20000 -> 2780000 | F38: =C38+D38+E38 -> 98360000 | G38: =80000*12*O18 -> 960000 | H38: =2300000*O18 -> 2300000 | I38: =2000000+500000*P18 -> 5500000 | J38: =SUM(C38:I38) -> 205480000 | K38: =C38/'Location Data'!$D$6 -> 24562.162 | L38: =J38/'Location Data'!$D$6 -> 55535.135 | N38: UGX | O38: 1350000 | P38: per sqm gfa all types | R38: =O38/'Location Data'!$D$6 -> 364.86486
A39: Four Bedroom Large Clerestory | B39: 106 | C39: =D19 -> 150520000 | D39: =1500000+50000*B39 -> 6800000 | E39: =500000+O19*1000000+B19*20000 -> 4620000 | F39: =C39+D39+E39 -> 161940000 | G39: =80000*12*O19 -> 1920000 | H39: =2300000*O19 -> 4600000 | I39: =2000000+500000*P19 -> 5500000 | J39: =SUM(C39:I39) -> 335900000 | K39: =C39/'Location Data'!$D$6 -> 40681.081 | L39: =J39/'Location Data'!$D$6 -> 90783.784 | O39: 1420000 | P39: per sqm gfa for clerestory | R39: =O39/'Location Data'!$D$6 -> 383.78378
A41: Kenya | C41: KES
A42: Model | B42: Floor area | C42: Basic structure | D42: Electricals | E42: Plumbing | F42: Total | G42: Tiling | H42: Sanitary wares | I42: Kitchen block | J42: Grand total | K42: Basic in USD | L42: Full in USD | N42: KES | O42: 52000 | P42: per sqm gfa all types | R42: =O42/'Location Data'!$D$12 -> 400 | S42: =R42/R38 -> 1.0962963
A43: Studio | B43: 25 | C43: =B43*$O$42 -> 1300000 | D43: =D25*($S$43+0.05)/'Location Data'!$D$6*'Location Data'!$D$12 -> 111345.17 | E43: =E25*($S$43+0.05)/'Location Data'!$D$6*'Location Data'!$D$12 -> 80978.302 | F43: =C43+D43+E43 -> 1492323.5 | G43: =G25*($S$43+0.05)/'Location Data'!$D$6*'Location Data'!$D$12 -> 38869.585 | H43: =H25*($S$43+0.05)/'Location Data'!$D$6*'Location Data'!$D$12 -> 93125.048 | I43: =I25*($S$43+0.05)/'Location Data'!$D$6*'Location Data'!$D$12 -> 182201.18 | J43: =SUM(C43:I43) -> 3298842.7 | K43: =C43/'Location Data'!$D$12 -> 10000 | L43: =J43/'Location Data'!$D$12 -> 25375.713 | O43: 55000 | P43: per sqm gfa for clerestory | R43: =O43/'Location Data'!$D$12 -> 423.07692 | S43: =R43/R39 -> 1.1023835
A44: One Bedroom Mono | B44: 37 | C44: =B44*$O$42 -> 1924000 | D44: =D26*($S$43+0.05)/'Location Data'!$D$6*'Location Data'!$D$12 -> 135638.66 | E44: =E26*($S$43+0.05)/'Location Data'!$D$6*'Location Data'!$D$12 -> 90695.699 | F44: =C44+D44+E44 -> 2150334.4 | G44: =G26*($S$43+0.05)/'Location Data'!$D$6*'Location Data'!$D$12 -> 38869.585 | H44: =H26*($S$43+0.05)/'Location Data'!$D$6*'Location Data'!$D$12 -> 93125.048 | I44: =I26*($S$43+0.05)/'Location Data'!$D$6*'Location Data'!$D$12 -> 182201.18 | J44: =SUM(C44:I44) -> 4614864.5 | K44: =C44/'Location Data'!$D$12 -> 14800 | L44: =J44/'Location Data'!$D$12 -> 35498.958
...

Sheet Bill of Quantities
A1: Bill of Quantities | D1: Specifications | M1: Item costs | P1: Project costs | Q1: Cost database | X1: Orderlist | AB1: =SUM(AB88:AB148) -> 14.33684 | AC1: =SUM(AC88:AC148) -> 15.106843 | AE1: =SUM(AE88:AE148) -> 0.7700037 | AF1: =AE1/AC1 -> 0.050970523
A2: # | B2: Unit | C2: Item | D2: Width (mm) | E2: Height (mm) | F2: Length (mm) | G2: Volume (m3) | H2: Weight (kg) | I2: Carbon storage (kg CO2) | J2: Labour (min) | K2: Structure | L2: Type | M2: Item cost ($) | N2: Labour cost ($) | O2: Total cost ($) | Q2: ='Location Data'!A6 -> Kampala, Uganda | R2: ='Location Data'!A7 -> West Nile, Uganda | S2: ='Location Data'!A8 -> Beira, Mozambique | T2: ='Location Data'!A9 -> Maputo, Mozambique | U2: ='Location Data'!A10 -> Accra, Ghana | V2: ='Location Data'!A11 -> Arusha, Tanzania | W2: ='Location Data'!A12 -> Nairobi, Kenya | X2: Sawn from | Y2: Gross fraction | Z2: Sum | AA2: Loss | AB2: Net vol | AC2: Gross vol | AD2: Gross vol / item | AE2: Project loss | AF2: Loss percentage
A4: Project name | C4: ='Project Costs'!B13
A5: ='Project Costs'!A14 -> Project Location | C5: ='Project Costs'!B14 -> Greater Kampala (<100km from factory)
A6: ='Project Costs'!A15 -> Client name | C6: ='Project Costs'!B15 -> Example calculation
A8: Country parameters | C8: Description | D8: Value
C9: Selected location | D9: ='Project Costs'!B11 -> Kampala, Uganda
C10: ='Location Data'!B5 -> Country | D10: {=INDEX('Location Data'!B:B,MATCH($D$9,'Location Data'!A:A,0),1)} -> Uganda
C11: ='Location Data'!G5 -> Distance from sawmill | D11: {=INDEX('Location Data'!G:G,MATCH($D$9,'Location Data'!A:A,0),1)} -> 100
C12: ='Location Data'!F5 -> Forestry partner | D12: {=INDEX('Location Data'!F:F,MATCH($D$9,'Location Data'!A:A,0),1)} -> Green Resources, Jinja
C13: ='Location Data'!H5 -> Timber species | D13: {=INDEX('Location Data'!H:H,MATCH($D$9,'Location Data'!A:A,0),1)} -> Pinus caribaea
C14: ='Location Data'!I5 -> Price per m3 (normal - ex vat, ex mill) | D14: =I14*G14 -> 252 | F14: Offcut loss | G14: 1 | H14: Bulk price | I14: {=INDEX('Location Data'!I:I,MATCH($D$9,'Location Data'!A:A,0),1)} -> 252
C15: ='Location Data'!J5 -> Price per m3 (profiled) | D15: =I15*G15 -> 260 | F15: Offcut loss | G15: 1 | H15: Bulk price | I15: {=INDEX('Location Data'!J:J,MATCH($D$9,'Location Data'!A:A,0),1)} -> 260
C16: ='Location Data'!K5 -> Timber density (wet) | D16: {=INDEX('Location Data'!K:K,MATCH($D$9,'Location Data'!A:A,0),1)} -> 561
C17: ='Location Data'!L5 -> Moisture content | D17: {=INDEX('Location Data'!L:L,MATCH($D$9,'Location Data'!A:A,0),1)} -> 0.12
C18: ='Location Data'!M5 -> Timber density (dry) | D18: {=INDEX('Location Data'!M:M,MATCH($D$9,'Location Data'!A:A,0),1)} -> 493
C19: ='Location Data'!N5 -> Carpenter cost (day) | D19: {=INDEX('Location Data'!N:N,MATCH($D$9,'Location Data'!A:A,0),1)} -> 15
C20: Carbon storage in CO2 per kg dry timber | D20: 1.833
A22: Screws and fasteners | Q22: Now calculating with mostly local prices
A23: =SUMIF('Structures Database'!B:B,C23,'Structures Database'!W:W) -> 2600 | B23: pcs | C23: Screw 3.5x40 small head screw SHS3540 | D23: 3.5 | F23: 40 | G23: =(D23/2)^2*PI()*F23/1000000000 -> 3.848451e-07 | H23: =G23*7700 -> 0.0029633073 | J23: 1 | K23: Screw | L23: Flooring | M23: =INDEX(23:23,1,MATCH($D$9,$2:$2,0)) -> 0.046297556 | N23: =J23*$D$19/(8*60) -> 0.03125 | O23: =M23+N23 -> 0.077547556 | P23: =A23*O23 -> 201.62365 | Q23: =0.0253*$X$26 -> 0.046297556 | R23: =$Q23 -> 0.046297556 | S23: =$Q23 -> 0.046297556 | T23: =$Q23 -> 0.046297556 | U23: =$Q23 -> 0.046297556 | V23: =$Q23 -> 0.046297556 | W23: =Q23 -> 0.046297556 | X23: Screw specs from Rotho Blaas now assumed with 25% import tax, 15% withholding tax, and 25% freight costs (USD 500 on USD 2500 order) across markets. VAT is added separately per country.
A24: =SUMIF('Structures Database'!B:B,C24,'Structures Database'!W:W) -> 0 | B24: pcs | C24: Screw 3.5x50 stainless small head screw SHS3550AS | D24: 3.5 | F24: 50 | G24: =(D24/2)^2*PI()*F24/1000000000 -> 4.8105638e-07 | H24: =G24*7700 -> 0.0037041341 | J24: 1 | K24: Screw | L24: Decking / Facade | M24: =INDEX(24:24,1,MATCH($D$9,$2:$2,0)) -> 0.070086815 | N24: =J24*$D$19/(8*60) -> 0.03125 | O24: =M24+N24 -> 0.10133681 | P24: =A24*O24 -> 0 | Q24: =0.0383*$X$26 -> 0.070086815 | R24: =$Q24 -> 0.070086815 | S24: =$Q24 -> 0.070086815 | T24: =$Q24 -> 0.070086815 | U24: =$Q24 -> 0.070086815 | V24: =$Q24 -> 0.070086815 | W24: =Q24 -> 0.070086815 | X24: Screw specs from Rotho Blaas now assumed with 25% import tax, 15% withholding tax, and 25% freight costs (USD 500 on USD 2500 order) across markets. VAT is added separately per country.
A25: =SUMIF('Structures Database'!B:B,C25,'Structures Database'!W:W) -> 0 | B25: pcs | C25: Screw 4 x 50 Stainless A2 SCA450 | D25: 4 | F25: 50 | G25: =(D25/2)^2*PI()*F25/1000000000 -> 6.2831853e-07 | H25: =G25*7700 -> 0.0048380527 | J25: 1 | K25: Screw | L25: Outdoor | M25: =INDEX(25:25,1,MATCH($D$9,$2:$2,0)) -> 0.1024768 | N25: =J25*$D$19/(8*60) -> 0.03125 | O25: =M25+N25 -> 0.1337268 | P25: =A25*O25 -> 0 | Q25: =0.056*$X$26 -> 0.1024768 | R25: =$Q25 -> 0.1024768 | S25: =$Q25 -> 0.1024768 | T25: =$Q25 -> 0.1024768 | U25: =$Q25 -> 0.1024768 | V25: =$Q25 -> 0.1024768 | W25: =Q25 -> 0.1024768 | X25: Import factor
A26: =SUMIF('Structures Database'!B:B,C26,'Structures Database'!W:W) -> 6101.8993 | B26: pcs | C26: Screw 4x40 semi threaded HBS440 | D26: 4 | F26: 40 | G26: =(D26/2)^2*PI()*F26/1000000000 -> 5.0265482e-07 | H26: =G26*7700 -> 0.0038704421 | J26: 1 | K26: Screw | L26: Boards | M26: =INDEX(26:26,1,MATCH($D$9,$2:$2,0)) -> 0.012 | N26: =J26*$D$19/(8*60) -> 0.03125 | O26: =M26+N26 -> 0.04325 | P26: =A26*O26 -> 263.90714 | Q26: 0.012 | R26: =$Q26 -> 0.012 | S26: =$Q26 -> 0.012 | T26: =$Q26 -> 0.012 | U26: =$Q26 -> 0.012 | V26: =$Q26 -> 0.012 | W26: =Q26 -> 0.012 | X26: =(2475+600+(0.35+0.06+0.015)*2475+680000/3700+218.45)/2475 -> 1.8299429
A27: =SUMIF('Structures Database'!B:B,C27,'Structures Database'!W:W) -> 3509.2015 | B27: pcs | C27: Screw 4x60 semi threaded HBS460 | D27: 4 | F27: 60 | G27: =(D27/2)^2*PI()*F27/1000000000 -> 7.5398224e-07 | H27: =G27*7700 -> 0.0058056632 | J27: 1 | K27: Screw | L27: Back Battens | M27: =INDEX(27:27,1,MATCH($D$9,$2:$2,0)) -> 0.018 | N27: =J27*$D$19/(8*60) -> 0.03125 | O27: =M27+N27 -> 0.04925 | P27: =A27*O27 -> 172.82817 | Q27: 0.018 | R27: =$Q27 -> 0.018 | S27: =$Q27 -> 0.018 | T27: =$Q27 -> 0.018 | U27: =$Q27 -> 0.018 | V27: =$Q27 -> 0.018 | W27: =Q27 -> 0.018
A28: =SUMIF('Structures Database'!B:B,C28,'Structures Database'!W:W) -> 0 | B28: pcs | C28: Screw 5x80 semi threaded HBS580 | D28: 5 | F28: 80 | G28: =(D28/2)^2*PI()*F28/1000000000 -> 1.5707963e-06 | H28: =G28*7700 -> 0.012095132 | J28: 1 | K28: Screw | L28: Frames | M28: =INDEX(28:28,1,MATCH($D$9,$2:$2,0)) -> 0.146 | N28: =J28*$D$19/(8*60) -> 0.03125 | O28: =M28+N28 -> 0.17725 | P28: =A28*O28 -> 0 | Q28: 0.146 | R28: =$Q28 -> 0.146 | S28: =$Q28 -> 0.146 | T28: =$Q28 -> 0.146 | U28: =$Q28 -> 0.146 | V28: =$Q28 -> 0.146 | W28: =Q28 -> 0.146
A29: =SUMIF('Structures Database'!B:B,C29,'Structures Database'!W:W) -> 949.02106 | B29: pcs | C29: Screw 6x100 semi threaded HBS6100 | D29: 6 | F29: 100 | G29: =(D29/2)^2*PI()*F29/1000000000 -> 2.8274334e-06 | H29: =G29*7700 -> 0.021771237 | J29: 1 | K29: Screw | L29: Frames | M29: =INDEX(29:29,1,MATCH($D$9,$2:$2,0)) -> 0.06 | N29: =J29*$D$19/(8*60) -> 0.03125 | O29: =M29+N29 -> 0.09125 | P29: =A29*O29 -> 86.598172 | Q29: 0.06 | R29: =$Q29 -> 0.06 | S29: =$Q29 -> 0.06 | T29: =$Q29 -> 0.06 | U29: =$Q29 -> 0.06 | V29: =$Q29 -> 0.06 | W29: =Q29 -> 0.06
A30: =SUMIF('Structures Database'!B:B,C30,'Structures Database'!W:W) -> 2574.4865 | B30: pcs | C30: Screw 6x120 semi threaded HBS6120 | D30: 6 | F30: 120 | G30: =(D30/2)^2*PI()*F30/1000000000 -> 3.3929201e-06 | H30: =G30*7700 -> 0.026125485 | J30: 1 | K30: Screw | L30: Frames | M30: =INDEX(30:30,1,MATCH($D$9,$2:$2,0)) -> 0.06 | N30: =J30*$D$19/(8*60) -> 0.03125 | O30: =M30+N30 -> 0.09125 | P30: =A30*O30 -> 234.92189 | Q30: 0.06 | R30: =$Q30 -> 0.06 | S30: =$Q30 -> 0.06 | T30: =$Q30 -> 0.06 | U30: =$Q30 -> 0.06 | V30: =$Q30 -> 0.06 | W30: =Q30 -> 0.06
A31: =SUMIF('Structures Database'!B:B,C31,'Structures Database'!W:W) -> 104 | B31: pcs | C31: Screw 6x160 semi threaded HBS6160 | D31: 6 | F31: 160 | G31: =(D31/2)^2*PI()*F31/1000000000 -> 4.5238934e-06 | H31: =G31*7700 -> 0.034833979 | J31: 1 | K31: Screw | L31: Frames | M31: =INDEX(31:31,1,MATCH($D$9,$2:$2,0)) -> 0.41891054 | N31: =J31*$D$19/(8*60) -> 0.03125 | O31: =M31+N31 -> 0.45016054 | P31: =A31*O31 -> 46.816696 | Q31: =0.22892*$X$26 -> 0.41891054 | R31: =$Q31 -> 0.41891054 | S31: =$Q31 -> 0.41891054 | T31: =$Q31 -> 0.41891054 | U31: =$Q31 -> 0.41891054 | V31: =$Q31 -> 0.41891054 | W31: =Q31 -> 0.41891054
A32: =SUMIF('Structures Database'!B:B,C32,'Structures Database'!W:W) -> 522.51866 | B32: pcs | C32: Corrugated roof screw 67 mm | D32: 6 | F32: 67 | G32: =(D32/2)^2*PI()*F32/1000000000 -> 1.8943804e-06 | H32: =G32*7700 -> 0.014586729 | J32: 1 | K32: Screw | L32: Roofing | M32: =INDEX(32:32,1,MATCH($D$9,$2:$2,0)) -> 0.11756757 | N32: =J32*$D$19/(8*60) -> 0.03125 | O32: =M32+N32 -> 0.14881757 | P32: =A32*O32 -> 77.759957 | Q32: =435/'Location Data'!$D$6 -> 0.11756757 | R32: =$Q32 -> 0.11756757 | S32: =$Q32 -> 0.11756757 | T32: =$Q32 -> 0.11756757 | U32: =$Q32 -> 0.11756757 | V32: =$Q32 -> 0.11756757 | W32: =Q32 -> 0.11756757
A34: Foundation materials
A35: =SUMIF('Structures Database'!B:B,C35,'Structures Database'!W:W) -> 25 | B35: pcs | C35: Foundation block | D35: 300 | E35: 400 | F35: 300 | G35: =D35*E35*F35/1000000000 -> 0.036 | H35: =G35*2400 -> 86.4 | I35: 0 | J35: 180 | K35: Foundation | L35: Point | M35: {=INDEX(35:35,1,MATCH($D$9,$2:$2,0))} -> 0 | N35: =J35*$D$19/(8*60) -> 5.625 | O35: =M35+N35 -> 5.625 | P35: =A35*O35 -> 140.625 | Q35: 0 | R35: 0 | S35: 0 | T35: 0 | U35: 0 | V35: 0 | W35: 0
A36: =SUMIF('Structures Database'!B:B,C36,'Structures Database'!W:W) -> 7.5 | B36: pcs | C36: Cement Bag 50 kg | I36: -0.6 | K36: Foundation | L36: Cement | M36: =37500/3700/1.18 -> 8.5890976 | N36: =J36*$D$19/(8*60) -> 0 | O36: =M36+N36 -> 8.5890976 | P36: =A36*O36 -> 64.418232
A37: =SUMIF('Structures Database'!B:B,C37,'Structures Database'!W:W) -> 0.75 | B37: tonnes | C37: Sand per tonne | K37: Foundation | L37: Anchor | M37: =135000/3/3700 -> 12.162162 | N37: =J37*$D$19/(8*60) -> 0 | O37: =M37+N37 -> 12.162162 | P37: =A37*O37 -> 9.1216216
A38: =SUMIF('Structures Database'!B:B,C38,'Structures Database'!W:W) -> 1 | B38: tonnes | C38: Aggregates per tonne | K38: Foundation | L38: Anchor | M38: =230000/3700 -> 62.162162 | N38: =J38*$D$19/(8*60) -> 0 | O38: =M38+N38 -> 62.162162 | P38: =A38*O38 -> 62.162162
A39: =SUMIF('Structures Database'!B:B,C39,'Structures Database'!W:W) -> 100 | B39: pcs | C39: M12 rod 200 mm (stainless steel) | D39: 16 | F39: 250 | G39: =(D39/2)^2*PI()*F39/1000000000 -> 5.0265482e-05 | K39: Foundation | L39: Rod | M39: 3 | N39: =J39*$D$19/(8*60) -> 0 | O39: =M39+N39 -> 3 | P39: =A39*O39 -> 300
A40: =SUMIF('Structures Database'!B:B,C40,'Structures Database'!W:W) -> 200 | B40: pcs | C40: M12 nut (stainless steel) | D40: 24 | E40: 24 | F40: 13 | K40: Foundation | L40: Nut | M40: 0.4 | N40: =J40*$D$19/(8*60) -> 0 | O40: =M40+N40 -> 0.4 | P40: =A40*O40 -> 80
A41: =SUMIF('Structures Database'!B:B,C41,'Structures Database'!W:W) -> 200 | B41: pcs | C41: M12 washer (stainless steel) | D41: 30 | F41: 3 | K41: Foundation | L41: Washer | M41: 0.2 | N41: =J41*$D$19/(8*60) -> 0 | O41: =M41+N41 -> 0.2 | P41: =A41*O41 -> 40
A42: =SUMIF('Structures Database'!B:B,C42,'Structures Database'!W:W) -> 100 | B42: pcs | C42: M12 drop anchor | D42: 20 | F42: 65 | K42: Foundation | L42: Anchor | M42: 1 | N42: =J42*$D$19/(8*60) -> 0 | O42: =M42+N42 -> 1 | P42: =A42*O42 -> 100
A43: =SUMIF('Structures Database'!B:B,C43,'Structures Database'!W:W) -> 2.5 | B43: pcs | C43: Y12 bar 12 metres | D43: 12 | F43: 12000 | G43: =(D43/2)^2*PI()*F43/1000000000 -> 0.001357168 | K43: Foundation | L43: Rebar | M43: =45000/1.18/3700 -> 10.306917 | N43: =J43*$D$19/(8*60) -> 0 | O43: =M43+N43 -> 10.306917 | P43: =A43*O43 -> 25.767293
A44: =SUMIF('Structures Database'!B:B,C44,'Structures Database'!W:W) -> 2.5 | B44: pcs | C44: 8 mm rebar 12 metres | D44: 8 | F44: 12000 | G44: =(D44/2)^2*PI()*F44/1000000000 -> 0.00060318579 | K44: Foundation | L44: Rebar | M44: =12000/1.18/3700 -> 2.7485112 | N44: =J44*$D$19/(8*60) -> 0 | O44: =M44+N44 -> 2.7485112 | P44: =A44*O44 -> 6.8712781
...

Sheet Timber Order
A3: Timber Procurement Order List
A4: Order date: | B4: Date
A5: By: | B5: Wolf Bierens - Easy Housing
A6: For: | B6: Contact Name - Company
A9: Timber quality and sustainability criteria
A10: Timber must be well seasoned, kiln dried, at specified dimensions within 2-3 mm tolerance and CCA treated. T&G, decking and shiplap planks must be planed and profiled properly.
A11: Timber must be sustainably sourced. This means with FSC (controlled) certification or under EUTR regulation.
A12: Easy Housing holds the legal claim to the construction stored carbon credits realised through its buildings. These credits do not conflict with any REDD+ or comparable forest conservation credits.
A14: Timber orderlist | D14: Specifications
A15: # | B15: Unit | C15: Item | D15: Width (mm) | E15: Height (mm) | F15: Length (mm) | G15: Volume (m3) | H15: Volume total | J15: Weight (kg) | K15: Carbon storage (kg CO2) | L15: Structure | M15: Type
A16: =ROUNDUP(SUMIF('Bill of Quantities'!X:X,C16,'Bill of Quantities'!Z:Z),0) -> 98 | B16: pcs | C16: =L16&" "&M16&" "&D16&" x "&E16&" x "&F16 -> Wall Beam 46 x 71 x 2450 | D16: 46 | E16: 71 | F16: 2450 | G16: =D16*E16*F16*0.000000001 -> 0.0080017 | H16: =A16*G16 -> 0.7841666 | J16: =G16*'Bill of Quantities'!$D$16 -> 4.4889537 | K16: =G16*'Bill of Quantities'!$D$18*'Bill of Quantities'!$D$20 -> 7.2308882 | L16: Wall | M16: Beam
A17: =ROUNDUP(SUMIF('Bill of Quantities'!X:X,C17,'Bill of Quantities'!Z:Z),0) -> 130 | B17: pcs | C17: =L17&" "&M17&" "&D17&" x "&E17&" x "&F17 -> Wall Beam 46 x 71 x 3650 | D17: 46 | E17: 71 | F17: 3650 | G17: =D17*E17*F17*0.000000001 -> 0.0119209 | H17: =A17*G17 -> 1.549717 | J17: =G17*'Bill of Quantities'!$D$16 -> 6.6876249 | K17: =G17*'Bill of Quantities'!$D$18*'Bill of Quantities'!$D$20 -> 10.772548 | L17: Wall | M17: Beam
A18: =ROUNDUP(SUMIF('Bill of Quantities'!X:X,C18,'Bill of Quantities'!Z:Z),0) -> 55 | B18: pcs | C18: =L18&" "&M18&" "&D18&" x "&E18&" x "&F18 -> Roof Beam 46 x 96 x 2450 | D18: 46 | E18: 96 | F18: 2450 | G18: =D18*E18*F18*0.000000001 -> 0.0108192 | H18: =A18*G18 -> 0.595056 | J18: =G18*'Bill of Quantities'!$D$16 -> 6.0695712 | K18: =G18*'Bill of Quantities'!$D$18*'Bill of Quantities'!$D$20 -> 9.7769756 | L18: Roof | M18: Beam
A19: =ROUNDUP(SUMIF('Bill of Quantities'!X:X,C19,'Bill of Quantities'!Z:Z),0) -> 3 | B19: pcs | C19: =L19&" "&M19&" "&D19&" x "&E19&" x "&F19 -> Roof Beam 46 x 96 x 4250 | D19: 46 | E19: 96 | F19: 4250 | G19: =D19*E19*F19*0.000000001 -> 0.018768 | H19: =A19*G19 -> 0.056304 | J19: =G19*'Bill of Quantities'!$D$16 -> 10.528848 | K19: =G19*'Bill of Quantities'!$D$18*'Bill of Quantities'!$D$20 -> 16.96006 | L19: Roof | M19: Beam
A20: =ROUNDUP(SUMIF('Bill of Quantities'!X:X,C20,'Bill of Quantities'!Z:Z),0) -> 61 | B20: pcs | C20: =L20&" "&M20&" "&D20&" x "&E20&" x "&F20 -> Roof Beam 46 x 96 x 5750 | D20: 46 | E20: 96 | F20: 5750 | G20: =D20*E20*F20*0.000000001 -> 0.025392 | H20: =A20*G20 -> 1.548912 | J20: =G20*'Bill of Quantities'!$D$16 -> 14.244912 | K20: =G20*'Bill of Quantities'!$D$18*'Bill of Quantities'!$D$20 -> 22.945963 | L20: Roof | M20: Beam
A21: =ROUNDUP(SUMIF('Bill of Quantities'!X:X,C21,'Bill of Quantities'!Z:Z),0) -> 96 | B21: pcs | C21: =L21&" "&M21&" "&D21&" x "&E21&" x "&F21 -> Floor Beam 46 x 146 x 2450 | D21: 46 | E21: 146 | F21: 2450 | G21: =D21*E21*F21*0.000000001 -> 0.0164542 | H21: =A21*G21 -> 1.5796032 | J21: =G21*'Bill of Quantities'!$D$16 -> 9.2308062 | K21: =G21*'Bill of Quantities'!$D$18*'Bill of Quantities'!$D$20 -> 14.86915 | L21: Floor | M21: Beam
A22: =ROUNDUP(SUMIF('Bill of Quantities'!X:X,C22,'Bill of Quantities'!Z:Z),0) -> 40 | B22: pcs | C22: =L22&" "&M22&" "&D22&" x "&E22&" x "&F22 -> Floor Beam 46 x 146 x 3050 | D22: 46 | E22: 146 | F22: 3050 | G22: =D22*E22*F22*0.000000001 -> 0.0204838 | H22: =A22*G22 -> 0.819352 | J22: =G22*'Bill of Quantities'!$D$16 -> 11.491412 | K22: =G22*'Bill of Quantities'!$D$18*'Bill of Quantities'!$D$20 -> 18.510575 | L22: Floor | M22: Beam
A23: =ROUNDUP(SUMIF('Bill of Quantities'!X:X,C23,'Bill of Quantities'!Z:Z),0) -> 0 | B23: pcs | C23: =L23&" "&M23&" "&D23&" x "&E23&" x "&F23 -> Floor Beam 46 x 146 x 5450 | D23: 46 | E23: 146 | F23: 5450 | G23: =D23*E23*F23*0.000000001 -> 0.0366022 | H23: =A23*G23 -> 0 | J23: =G23*'Bill of Quantities'!$D$16 -> 20.533834 | K23: =G23*'Bill of Quantities'!$D$18*'Bill of Quantities'!$D$20 -> 33.076273 | L23: Floor | M23: Beam
A24: =ROUNDUP(SUMIF('Bill of Quantities'!X:X,C24,'Bill of Quantities'!Z:Z),0) -> 0 | B24: pcs | C24: =L24&" "&M24&" "&D24&" x "&E24&" x "&F24 -> Timber Column 100 x 100 x 3050 | D24: 100 | E24: 100 | F24: 3050 | G24: =D24*E24*F24*0.000000001 -> 0.0305 | H24: =A24*G24 -> 0 | J24: =G24*'Bill of Quantities'!$D$16 -> 17.1105 | K24: =G24*'Bill of Quantities'!$D$18*'Bill of Quantities'!$D$20 -> 27.561905 | L24: Timber | M24: Column
A25: =ROUNDUP(SUMIF('Bill of Quantities'!X:X,C25,'Bill of Quantities'!Z:Z),0) -> 309 | B25: pcs | C25: =L25&" "&M25&" "&D25&" x "&E25&" x "&F25 -> Timber Back Batten 22 x 46 x 2450 | D25: 22 | E25: 46 | F25: 2450 | G25: =D25*E25*F25*0.000000001 -> 0.0024794 | H25: =A25*G25 -> 0.7661346 | J25: =G25*'Bill of Quantities'!$D$16 -> 1.3909434 | K25: =G25*'Bill of Quantities'!$D$18*'Bill of Quantities'!$D$20 -> 2.2405569 | L25: Timber | M25: Back Batten
A26: =ROUNDUP(SUMIF('Bill of Quantities'!X:X,C26,'Bill of Quantities'!Z:Z),0) -> 16 | B26: pcs | C26: =L26&" "&M26&" "&D26&" x "&E26&" x "&F26 -> Timber Back Batten 22 x 46 x 3050 | D26: 22 | E26: 46 | F26: 3050 | G26: =D26*E26*F26*0.000000001 -> 0.0030866 | H26: =A26*G26 -> 0.0493856 | J26: =G26*'Bill of Quantities'!$D$16 -> 1.7315826 | K26: =G26*'Bill of Quantities'!$D$18*'Bill of Quantities'!$D$20 -> 2.7892647 | L26: Timber | M26: Back Batten
A27: =ROUNDUP(SUMIF('Bill of Quantities'!X:X,C27,'Bill of Quantities'!Z:Z),0) -> 550 | B27: pcs | C27: =L27&" "&M27&" "&D27&" x "&E27&" x "&F27 -> Timber Floor Plank 22 x 96 x 2450 | D27: 22 | E27: 96 | F27: 2450 | G27: =D27*E27*F27*0.000000001 -> 0.0051744 | H27: =A27*G27 -> 2.84592 | J27: =G27*'Bill of Quantities'!$D$16 -> 2.9028384 | K27: =G27*'Bill of Quantities'!$D$18*'Bill of Quantities'!$D$20 -> 4.6759449 | L27: Timber | M27: Floor Plank
